Workbook

Sheet 175
A1: Probability | B1: NA | C1: Q1 21 | D1: Q2 21 | E1: Q3 21 | F1: Q4 21 | G1: Q1 22 | H1: Q2 22 | I1: Q3 22 | J1: Q4 22 | K1: Q1 23 | L1: Q2 23 | M1: Q3 23 | N1: Q4 23
A2: Q1 21 | C2: 0.13 | D2: 0.43 | E2: 0.36 | F2: 0.08
A3: Q2 21 | D3: 0.13 | E3: 0.43 | F3: 0.36 | G3: 0.08
A4: Q3 21 | E4: 0.13 | F4: 0.43 | G4: 0.36 | H4: 0.08
A5: Q4 21 | F5: 0.13 | G5: 0.43 | H5: 0.36 | I5: 0.08
A6: Q1 22 | G6: 0.13 | H6: 0.43 | I6: 0.36 | J6: 0.08
A7: Q2 22 | H7: 0.13 | I7: 0.43 | J7: 0.36 | K7: 0.08
A8: Q3 22 | I8: 0.13 | J8: 0.43 | K8: 0.36 | L8: 0.08
A9: Q4 22 | J9: 0.13 | K9: 0.43 | L9: 0.36 | M9: 0.08
A10: Q1 23 | K10: 0.13 | L10: 0.43 | M10: 0.36 | N10: 0.08
A11: Q2 23 | L11: 0.13 | M11: 0.43 | N11: 0.36
A12: Q3 23 | M12: 0.13 | N12: 0.43
A13: Q4 23 | N13: 0.13
B14: Opps | C14: Q1 21 | D14: Q2 21 | E14: Q3 21 | F14: Q4 21 | G14: Q1 22 | H14: Q2 22 | I14: Q3 22 | J14: Q4 22 | K14: Q1 23 | L14: Q2 23 | M14: Q3 23 | N14: Q4 23
A15: Q1 21 | B15: 29 | C15: =$B15*C2 -> 3.77 | D15: =$B15*D2 -> 12.47 | E15: =$B15*E2 -> 10.44 | F15: =$B15*F2 -> 2.32
A16: Q2 21 | B16: =15+11+6 -> 32 | D16: =$B16*D3 -> 4.16 | E16: =$B16*E3 -> 13.76 | F16: =$B16*F3 -> 11.52 | G16: =$B16*G3 -> 2.56
A17: Q3 21 | B17: =30+19+20 -> 69 | E17: =$B17*E4 -> 8.97 | F17: =$B17*F4 -> 29.67 | G17: =$B17*G4 -> 24.84 | H17: =$B17*H4 -> 5.52
A18: Q4 21 | B18: =16+28+16 -> 60 | F18: =$B18*F5 -> 7.8 | G18: =$B18*G5 -> 25.8 | H18: =$B18*H5 -> 21.6 | I18: =$B18*I5 -> 4.8
A19: Q1 22 | B19: =16+23+34 -> 73 | G19: =$B19*G6 -> 9.49 | H19: =$B19*H6 -> 31.39 | I19: =$B19*I6 -> 26.28 | J19: =$B19*J6 -> 5.84
A20: Q2 22 | B20: 76 | H20: =$B20*H7 -> 9.88 | I20: =$B20*I7 -> 32.68 | J20: =$B20*J7 -> 27.36 | K20: =$B20*K7 -> 6.08
A21: Q3 22 | B21: 150 | I21: =$B21*I8 -> 19.5 | J21: =$B21*J8 -> 64.5 | K21: =$B21*K8 -> 54 | L21: =$B21*L8 -> 12
A22: Q4 22 | B22: 150 | J22: =$B22*J9 -> 19.5 | K22: =$B22*K9 -> 64.5 | L22: =$B22*L9 -> 54 | M22: =$B22*M9 -> 12
A23: Q1 23 | B23: 150 | K23: =$B23*K10 -> 19.5 | L23: =$B23*L10 -> 64.5 | M23: =$B23*M10 -> 54 | N23: =$B23*N10 -> 12
A24: Q2 23 | B24: 150 | L24: =$B24*L11 -> 19.5 | M24: =$B24*M11 -> 64.5 | N24: =$B24*N11 -> 54
A25: Q3 23 | B25: 150 | M25: =$B25*M12 -> 19.5 | N25: =$B25*N12 -> 64.5
A26: Q4 23 | B26: 150 | N26: =$B26*N13 -> 19.5
A27: Total Opps | C27: =sum(C15:C26) -> 3.77 | D27: =sum(D15:D26) -> 16.63 | E27: =sum(E15:E26) -> 33.17 | F27: =sum(F15:F26) -> 51.31 | G27: =sum(G15:G26) -> 62.69 | H27: =sum(H15:H26) -> 68.39 | I27: =sum(I15:I26) -> 83.26 | J27: =sum(J15:J26) -> 117.2 | ... N27: =sum(N15:N26) -> 150
A28: Target (175) | C28: 775000 | D28: 775000 | E28: 775000 | F28: 775000 | G28: 582000 | H28: 749000 | I28: 1722115 | J28: 2322449 | K28: 2322449 | L28: 2322449 | M28: 2322449 | N28: 2322449
A29: ARR | C29: - | D29: - | E29: - | F29: - | G29: =3267624+G28 -> 3849624 | H29: =G29+H28 -> 4598624 | I29: =H29+I28 -> 6320739 | J29: =I29+J28 -> 8643188 | K29: =J29+K28 -> 10965637 | L29: =K29+L28 -> 13288086 | M29: =L29+M28 -> 15610535 | N29: =M29+N28 -> 17932984 | O29: =N29/J29 -> 2.0748113
A30: Average ARR | C30: 35000 | D30: 35000 | E30: 35000 | F30: 35000 | G30: 35000 | H30: 35000 | I30: 45000 | J30: 45000 | K30: 45000 | L30: 45000 | M30: 45000 | N30: 45000
A31: Pipeline Cover | C31: 2 | D31: 2 | E31: 2 | F31: 2 | G31: 2 | H31: 2.5 | I31: 3 | J31: 3 | K31: 3 | L31: 3 | M31: 3 | N31: 3
A32: Opps Required | C32: =(C28/C30)*C31 -> 44.285714 | D32: =(D28/D30)*D31 -> 44.285714 | E32: =(E28/E30)*E31 -> 44.285714 | F32: =(F28/F30)*F31 -> 44.285714 | G32: =(G28/G30)*G31 -> 33.257143 | H32: =(H28/H30)*H31 -> 53.5 | I32: =(I28/I30)*I31 -> 114.80767 | J32: =(J28/J30)*J31 -> 154.82993 | ... N32: =(N28/N30)*N31 -> 154.82993
A33: Delta Opps | C33: =C32-C27 -> 40.515714 | D33: =D32-D27 -> 27.655714 | E33: =E32-E27 -> 11.115714 | F33: =F32-F27 -> -7.0242857 | G33: =G32-G27 -> -29.432857 | H33: =H32-H27 -> -14.89 | I33: =I32-I27 -> 31.547667 | J33: =J32-J27 -> 37.629933 | ... N33: =N32-N27 -> 4.8299333
A34: Operating % | C34: =C27/C32 -> 0.085129032 | D34: =D27/D32 -> 0.37551613 | E34: =E27/E32 -> 0.749 | F34: =F27/F32 -> 1.1586129 | G34: =G27/G32 -> 1.8850086 | H34: =H27/H32 -> 1.2783178 | I34: =I27/I32 -> 0.72521289 | J34: =J27/J32 -> 0.75695957 | ... N34: =N27/N32 -> 0.96880491
A35: Fully ramped QCs | C35: 0 | D35: 0 | E35: 0 | F35: 1 | G35: 1 | H35: 1 | I35: 5 | J35: 5 | K35: 7 | L35: 9 | M35: 9 | N35: 9
A36: Opp Capacity | C36: =C35*13 -> 0 | D36: =D35*13 -> 0 | E36: =E35*13 -> 0 | F36: =F35*13 -> 13 | G36: =G35*13 -> 13 | H36: =H35*13 -> 13 | I36: =I35*13 -> 65 | J36: =J35*13 -> 65 | ... N36: =N35*13 -> 117
A37: Delta QCs | C37: =C36-C32 -> -44.285714 | D37: =D36-D32 -> -44.285714 | E37: =E36-E32 -> -44.285714 | F37: =F36-F32 -> -31.285714 | G37: =G36-G32 -> -20.257143 | H37: =H36-H32 -> -40.5 | I37: =I36-I32 -> -49.807667 | J37: =J36-J32 -> -89.829933 | ... N37: =N36-N32 -> -37.829933
A40: 2022 Opps at current run rate | B40: 152
A41: 2022 target opps | B41: =sum(B21:B22) -> 300
A42: Delta | B42: =B41-B40 -> 148

Sheet 128
A1: Probability | B1: NA | E1: Q1 21 | F1: Q2 21 | G1: Q3 21 | H1: Q4 21 | I1: Q1 22 | J1: Q2 22 | K1: Q3 22 | L1: Q4 22 | M1: Q1 23 | N1: Q2 23 | O1: Q3 23 | P1: Q4 23
A2: Q1 21 | E2: 0.13 | F2: 0.43 | G2: 0.36 | H2: 0.08
A3: Q2 21 | F3: 0.13 | G3: 0.43 | H3: 0.36 | I3: 0.08
A4: Q3 21 | G4: 0.13 | H4: 0.43 | I4: 0.36 | J4: 0.08
A5: Q4 21 | H5: 0.13 | I5: 0.43 | J5: 0.36 | K5: 0.08
A6: Q1 22 | I6: 0.13 | J6: 0.43 | K6: 0.36 | L6: 0.08
A7: Q2 22 | J7: 0.13 | K7: 0.43 | L7: 0.36 | M7: 0.08
A8: Q3 22 | K8: 0.13 | L8: 0.43 | M8: 0.36 | N8: 0.08
A9: Q4 22 | L9: 0.13 | M9: 0.43 | N9: 0.36 | O9: 0.08
A10: Q1 23 | M10: 0.17 | N10: 0.5 | O10: 0.3 | P10: 0.03
A11: Q2 23 | N11: 0.17 | O11: 0.5 | P11: 0.3
A12: Q3 23 | O12: 0.17 | P12: 0.5
A13: Q4 23 | P13: 0.17
B14: Opps | C14: Marketing Opps | D14: Budget () | E14: Q1 21 | F14: Q2 21 | G14: Q3 21 | H14: Q4 21 | I14: Q1 22 | J14: Q2 22 | K14: Q3 22 | L14: Q4 22 | M14: Q1 23 | N14: Q2 23 | O14: Q3 23 | P14: Q4 23
A15: Q1 21 | B15: 29 | E15: =$B15*E2 -> 3.77 | F15: =$B15*F2 -> 12.47 | G15: =$B15*G2 -> 10.44 | H15: =$B15*H2 -> 2.32
A16: Q2 21 | B16: =15+11+6 -> 32 | F16: =$B16*F3 -> 4.16 | G16: =$B16*G3 -> 13.76 | H16: =$B16*H3 -> 11.52 | I16: =$B16*I3 -> 2.56
A17: Q3 21 | B17: =30+19+20 -> 69 | G17: =$B17*G4 -> 8.97 | H17: =$B17*H4 -> 29.67 | I17: =$B17*I4 -> 24.84 | J17: =$B17*J4 -> 5.52
A18: Q4 21 | B18: =16+28+16 -> 60 | H18: =$B18*H5 -> 7.8 | I18: =$B18*I5 -> 25.8 | J18: =$B18*J5 -> 21.6 | K18: =$B18*K5 -> 4.8
A19: Q1 22 | B19: =16+23+34 -> 73 | D19: 657933 | I19: =$B19*I6 -> 9.49 | J19: =$B19*J6 -> 31.39 | K19: =$B19*K6 -> 26.28 | L19: =$B19*L6 -> 5.84
A20: Q2 22 | B20: 76 | D20: 852976 | J20: =$B20*J7 -> 9.88 | K20: =$B20*K7 -> 32.68 | L20: =$B20*L7 -> 27.36 | M20: =$B20*M7 -> 6.08
A21: Q3 22 | B21: =23*3.5 -> 80.5 | C21: =B21*0.7 -> 56.35 | D21: 1038700 | K21: =$B21*K8 -> 10.465 | L21: =$B21*L8 -> 34.615 | M21: =$B21*M8 -> 28.98 | N21: =$B21*N8 -> 6.44
A22: Q4 22 | B22: =32*3.5 -> 112 | C22: =B22*0.75 -> 84 | D22: 834200 | L22: =$B22*L9 -> 14.56 | M22: =$B22*M9 -> 48.16 | N22: =$B22*N9 -> 40.32 | O22: =$B22*O9 -> 8.96
A23: Q1 23 | B23: =26*3.5 -> 91 | C23: =B23*0.75 -> 68.25 | D23: 645203 | M23: =$B23*M10 -> 15.47 | N23: =$B23*N10 -> 45.5 | O23: =$B23*O10 -> 27.3 | P23: =$B23*P10 -> 2.73 | Q23: =D23/C23 -> 9453.5238
A24: Q2 23 | B24: =34*3.5 -> 119 | C24: =B24*0.75 -> 89.25 | D24: 677625 | N24: =$B24*N11 -> 20.23 | O24: =$B24*O11 -> 59.5 | P24: =$B24*P11 -> 35.7 | Q24: =D24/C24 -> 7592.437
A25: Q3 23 | B25: =35*3.5 -> 122.5 | C25: =B25*0.75 -> 91.875 | D25: 616219 | O25: =$B25*O12 -> 20.825 | P25: =$B25*P12 -> 61.25 | Q25: =D25/C25 -> 6707.1456
A26: Q4 23 | B26: =35*3.5 -> 122.5 | C26: =B26*0.75 -> 91.875 | D26: 616219 | P26: =$B26*P13 -> 20.825 | Q26: =D26/C26 -> 6707.1456
A27: Total Opps | E27: =sum(E15:E26) -> 3.77 | F27: =sum(F15:F26) -> 16.63 | G27: =sum(G15:G26) -> 33.17 | H27: =sum(H15:H26) -> 51.31 | I27: =sum(I15:I26) -> 62.69 | J27: =sum(J15:J26) -> 68.39 | K27: =sum(K15:K26) -> 74.225 | L27: =sum(L15:L26) -> 82.375 | ... P27: =sum(P15:P26) -> 120.505
A28: Target (125) | E28: - | F28: - | G28: - | H28: - | I28: 582000 | J28: 749000 | K28: 1041247 | L28: 1428099 | M28: =($J$28/$I$28)*L28 -> 1837880 | N28: =M28 -> 1837880 | O28: =N28 -> 1837880 | P28: =O28 -> 1837880
A29: ARR | E29: - | F29: - | G29: - | H29: - | I29: =3267624+I28 -> 3849624 | J29: =I29+J28 -> 4598624 | K29: =J29+K28 -> 5639871 | L29: =K29+L28 -> 7067970 | M29: =L29+M28 -> 8905850 | N29: =M29+N28 -> 10743730 | O29: =N29+O28 -> 12581610 | P29: =O29+P28 -> 14419490
A30: Average ARR | E30: 35000 | F30: 35000 | G30: 35000 | H30: 35000 | I30: 35000 | J30: 35000 | K30: 45000 | L30: 45000 | M30: 45000 | N30: 45000 | O30: 45000 | P30: 45000
A31: Pipeline Cover | E31: 2 | F31: 2 | G31: 2 | H31: 2 | I31: 2 | J31: 2.5 | K31: 3 | L31: 3 | M31: 3 | N31: 3 | O31: 3 | P31: 3
A32: Opps Required | E32: - | F32: - | G32: - | H32: - | I32: =(I28/I30)*I31 -> 33.257143 | J32: =(J28/J30)*J31 -> 53.5 | K32: =(K28/K30)*K31 -> 69.416467 | L32: =(L28/L30)*L31 -> 95.2066 | M32: =(M28/M30)*M31 -> 122.52533 | N32: =(N28/N30)*N31 -> 122.52533 | O32: =(O28/O30)*O31 -> 122.52533 | P32: =(P28/P30)*P31 -> 122.52533
A33: Delta Opps | E33: - | F33: - | G33: - | H33: - | I33: =I32-I27 -> -29.432857 | J33: =J32-J27 -> -14.89 | K33: =K32-K27 -> -4.8085333 | L33: =L32-L27 -> 12.8316 | M33: =M32-M27 -> 23.835332 | N33: =N32-N27 -> 10.035332 | O33: =O32-O27 -> 5.9403323 | P33: =P32-P27 -> 2.0203323
A34: Operating % | E34: -% | F34: -% | G34: -% | H34: -% | I34: =I27/I32 -> 1.8850086 | J34: =J27/J32 -> 1.2783178 | K34: =K27/K32 -> 1.0692708 | L34: =L27/L32 -> 0.86522363 | M34: =M27/M32 -> 0.80546609 | N34: =N27/N32 -> 0.91809586 | O34: =O27/O32 -> 0.95151752 | P34: =P27/P32 -> 0.9835109
A35: Fully ramped QCs | E35: 0 | F35: 0 | G35: 0 | H35: 1 | I35: 1 | J35: 1 | K35: 5 | L35: 5 | M35: 7 | N35: 9 | O35: 9 | P35: 9
A36: Opp Capacity | E36: =E35*13 -> 0 | F36: =F35*13 -> 0 | G36: =G35*13 -> 0 | H36: =H35*13 -> 13 | I36: =I35*13 -> 13 | J36: =J35*13 -> 13 | K36: =K35*13 -> 65 | L36: =L35*13 -> 65 | ... P36: =P35*13 -> 117
A37: Delta QCs | E37: - | F37: - | G37: - | H37: - | I37: =I36-I32 -> -20.257143 | J37: =J36-J32 -> -40.5 | K37: =K36-K32 -> -4.4164667 | L37: =L36-L32 -> -30.2066 | M37: =M36-M32 -> -31.525332 | N37: =N36-N32 -> -5.5253323 | O37: =O36-O32 -> -5.5253323 | P37: =P36-P32 -> -5.5253323
A40: 2022 Opps at current run rate | B40: 152
A41: 2022 target opps | B41: =sum(B21:B22) -> 192.5
A42: Delta | B42: =B41-B40 -> 40.5
...

Sheet 2023 Overview
B1: Closing CARR | C1: Opening ARR | D1: Growth Rate
A2: Downside | B2: 10700000 | C2: 6455827 | D2: =(B2-C2)/C2 -> 0.6574174
A3: Base | B3: 12900000 | C3: 6455827 | D3: =(B3-C3)/C3 -> 0.99819481
A4: Upside | B4: 13600000 | C4: 6455827 | D4: =(B4-C4)/C4 -> 1.106624
A5: Current Forecast | B5: ='2023-AS IS'!X40 -> 10425661 | C5: 6455827 | D5: =(B5-C5)/C5 -> 0.61492256
A6: Revised Forecast | B6: ='2023-TO BE'!X40 -> 11409396 | C6: 6455827 | D6: =(B6-C6)/C6 -> 0.76730208
A8: Run Rate SQLs | B8: =sum('2023-AS IS'!B23:B26) -> 588
A9: Run Rate SQL-D | B9: =79/110*B8 -> 422.29091
A10: Run Rate SQL-W | B10: =B8-B9 -> 165.70909
A11: Delta SQLs + Headroom | B11: =(sum('2023-TO BE'!B23:B26)-B8)*1.1 -> 136.4
A12: Delta SQL-D | B12: =B11-B13 -> 78.74
A13: Delta SQL-W | B13: =(B10/B8)*0.15/0.1*B11 -> 57.66
A14: MQL Required | B14: =B12/0.25 -> 314.96
A15: Marketing Spend Re | B15: =B14*'2023-TO BE'!Y26*0.09 -> 275779.71

Sheet 2023-AS IS
A1: Probability | C1: Q2 22 | D1: Q3 22 | E1: Q4 22 | F1: Q1 23 | G1: Q2 23 | H1: Q3 23 | I1: Q4 23 | J1: NA | M1: Q1 21 | N1: Q2 21 | O1: Q3 21 | P1: Q4 21 | Q1: Q1 22 | R1: Q2 22 | S1: Q3 22 | T1: Q4 22 | U1: Q1 23 | V1: Q2 23 | W1: Q3 23 | X1: Q4 23 | Y1: Average marketing cost per opp ()
A2: Q1 21 | M2: 0.13 | N2: 0.43 | O2: 0.36 | P2: 0.08
A3: Q2 21 | N3: 0.13 | O3: 0.43 | P3: 0.36 | Q3: 0.08
A4: Q3 21 | O4: 0.13 | P4: 0.43 | Q4: 0.36 | R4: 0.08
A5: Q4 21 | P5: 0.13 | Q5: 0.43 | R5: 0.36 | S5: 0.08
A6: Q1 22 | C6: 0.1 | D6: 0.01 | Q6: 0.13 | R6: 0.43 | S6: 0.36 | T6: 0.08
A7: Q2 22 | C7: =227/255 -> 0.89019608 | D7: 0.1 | E7: 0.01 | R7: 0.13 | S7: 0.43 | T7: 0.36 | U7: 0.11
A8: Q3 22 | D8: =227/255 -> 0.89019608 | E8: 0.1 | F8: 0.01 | S8: 0.13 | T8: 0.43 | U8: 0.26 | V8: 0.11
A9: Q4 22 | E9: =227/255 -> 0.89019608 | F9: 0.1 | G9: 0.01 | T9: 0.13 | U9: 0.4 | V9: 0.26 | W9: 0.11
A10: Q1 23 | F10: =227/255 -> 0.89019608 | G10: 0.1 | H10: 0.01 | U10: 0.23 | V10: 0.4 | W10: 0.26 | X10: 0.11
A11: Q2 23 | G11: =227/255 -> 0.89019608 | H11: 0.1 | I11: 0.01 | V11: 0.23 | W11: 0.4 | X11: 0.26
A12: Q3 23 | H12: =227/255 -> 0.89019608 | I12: 0.1 | W12: 0.23 | X12: 0.4
A13: Q4 23 | I13: 0.89 | X13: 0.13
B14: SQLs | C14: Q2 22 | D14: Q3 22 | E14: Q4 22 | F14: Q1 23 | G14: Q2 23 | H14: Q3 23 | I14: Q4 23 | J14: Opps | K14: Marketing Opps | L14: Budget () | M14: Q1 21 | N14: Q2 21 | O14: Q3 21 | P14: Q4 21 | Q14: Q1 22 | R14: Q2 22 | S14: Q3 22 | T14: Q4 22 | U14: Q1 23 | V14: Q2 23 | W14: Q3 23 | X14: Q4 23 | Z14: QC Required
A15: Q1 21 | J15: 29 | M15: =$J15*M2 -> 3.77 | N15: =$J15*N2 -> 12.47 | O15: =$J15*O2 -> 10.44 | P15: =$J15*P2 -> 2.32
A16: Q2 21 | J16: =15+11+6 -> 32 | N16: =$J16*N3 -> 4.16 | O16: =$J16*O3 -> 13.76 | P16: =$J16*P3 -> 11.52 | Q16: =$J16*Q3 -> 2.56
A17: Q3 21 | J17: =30+19+20 -> 69 | O17: =$J17*O4 -> 8.97 | P17: =$J17*P4 -> 29.67 | Q17: =$J17*Q4 -> 24.84 | R17: =$J17*R4 -> 5.52
A18: Q4 21 | J18: =16+28+16 -> 60 | P18: =$J18*P5 -> 7.8 | Q18: =$J18*Q5 -> 25.8 | R18: =$J18*R5 -> 21.6 | S18: =$J18*S5 -> 4.8
A19: Q1 22 | B19: 56 | C19: =$B19*C6 -> 5.6 | J19: =16+23+34 -> 73 | L19: 657933 | Q19: =$J19*Q6 -> 9.49 | R19: =$J19*R6 -> 31.39 | S19: =$J19*S6 -> 26.28 | T19: =$J19*T6 -> 5.84
A20: Q2 22 | B20: 128 | C20: =$B20*C7 -> 113.9451 | D20: =$B20*D7 -> 12.8 | J20: 91 | L20: 852976 | R20: =$J20*R7 -> 11.83 | S20: =$J20*S7 -> 39.13 | T20: =$J20*T7 -> 32.76 | U20: =$J20*U7 -> 10.01
A21: Q3 22 | B21: 190 | D21: =$B21*D8 -> 169.13725 | E21: =$B21*E8 -> 19 | F21: =$B21*F8 -> 1.9 | J21: 83 | K21: =J21*0.75 -> 62.25 | L21: 1038700 | S21: =$J21*S8 -> 10.79 | T21: =$J21*T8 -> 35.69 | U21: =$J21*U8 -> 21.58 | V21: =$J21*V8 -> 9.13 | Y21: =L21/K21 -> 16685.944 | Z21: =J21/15 -> 5.5333333
A22: Q4 22 | B22: 144 | E22: =$B22*E9 -> 128.18824 | F22: =$B22*F9 -> 14.4 | G22: =$B22*G9 -> 1.44 | J22: 94 | K22: =J22*0.75 -> 70.5 | L22: 834200 | T22: =$J22*T9 -> 12.22 | U22: =$J22*U9 -> 37.6 | V22: =$J22*V9 -> 24.44 | W22: =$J22*W9 -> 10.34 | Y22: =L22/K22 -> 11832.624 | Z22: =J22/15 -> 6.2666667
A23: Q1 23 | B23: 147 | F23: =$B23*F10 -> 130.85882 | G23: =$B23*G10 -> 14.7 | H23: =$B23*H10 -> 1.47 | J23: =(70/(31+28+14))*(31+28+31) -> 86.30137 | K23: =J23*0.75 -> 64.726027 | L23: 645203 | U23: =$J23*U10 -> 19.849315 | V23: =$J23*V10 -> 34.520548 | W23: =$J23*W10 -> 22.438356 | X23: =$J23*X10 -> 9.4931507 | Y23: =L23/K23 -> 9968.2157 | Z23: =J23/15 -> 5.7534247
A24: Q2 23 | B24: 147 | G24: =$B24*G11 -> 130.85882 | H24: =$B24*H11 -> 14.7 | I24: =$B24*I11 -> 1.47 | J24: =G29 -> 80.849353 | K24: =J24*0.75 -> 60.637015 | L24: 677625 | V24: =$J24*V11 -> 18.595351 | W24: =$J24*W11 -> 32.339741 | X24: =$J24*X11 -> 21.020832 | Y24: =L24/K24 -> 11175.105 | Z24: =J24/15 -> 5.3899569
A25: Q3 23 | B25: 147 | H25: =$B25*H12 -> 130.85882 | I25: =$B25*I12 -> 14.7 | J25: =H29 -> 80.865853 | K25: =J25*0.75 -> 60.64939 | L25: 677625 | W25: =$J25*W12 -> 18.599146 | X25: =$J25*X12 -> 32.346341 | Y25: =L25/K25 -> 11172.825 | Z25: =J25/15 -> 5.3910569
A26: Q4 23 | B26: 147 | I26: =$B26*I13 -> 130.83 | J26: =I29 -> 80.85 | K26: =J26*0.75 -> 60.6375 | L26: 677625 | X26: =$J26*X13 -> 10.5105 | Y26: =L26/K26 -> 11175.015 | Z26: =J26/15 -> 5.39
A27: Total SQLs | C27: =sum(C19:C26) -> 119.5451 | D27: =sum(D19:D26) -> 181.93725 | E27: =sum(E19:E26) -> 147.18824 | F27: =sum(F19:F26) -> 147.15882 | G27: =sum(G19:G26) -> 146.99882 | H27: =sum(H19:H26) -> 147.02882 | I27: =sum(I19:I26) -> 147
A28: Conversion | C28: =0.5 -> 0.5 | D28: =0.5 -> 0.5 | E28: =0.5 -> 0.5 | F28: 0.55 | G28: 0.55 | H28: 0.55 | I28: 0.55
A29: Forecasted Opps | C29: =C27*C28 -> 59.772549 | D29: =D27*D28 -> 90.968627 | E29: =E27*E28 -> 73.594118 | F29: =F27*F28 -> 80.937353 | G29: =G27*G28 -> 80.849353 | H29: =H27*H28 -> 80.865853 | I29: =I27*I28 -> 80.85
A30: Delta to Actual | F30: =F29-J23 -> -5.3640169 | G30: =G29-J24 -> 0 | H30: =H29-J25 -> 0 | I30: =I29-J26 -> 0
A31: Total Opps | M31: =sum(M15:M26) -> 3.77 | N31: =sum(N15:N26) -> 16.63 | O31: =sum(O15:O26) -> 33.17 | P31: =sum(P15:P26) -> 51.31 | Q31: =sum(Q15:Q26) -> 62.69 | R31: =sum(R15:R26) -> 70.34 | S31: =sum(S15:S26) -> 81 | T31: =sum(T15:T26) -> 86.51 | ... X31: =sum(X15:X26) -> 73.370824
A32: Base Target | M32: - | N32: - | O32: - | P32: - | Q32: 582000 | R32: 749000 | S32: 1204000 | T32: 1750000 | U32: 1375000 | V32: 1700000 | W32: =V32 -> 1700000 | X32: =W32 -> 1700000
A33: ARR | M33: - | N33: - | O33: - | P33: - | Q33: =3267624+Q32 -> 3849624 | R33: =Q33+R32 -> 4598624 | S33: =R33+S32 -> 5802624 | T33: =S33+T32 -> 7552624 | U33: =T33+U32 -> 8927624 | V33: =U33+V32 -> 10627624 | W33: =V33+W32 -> 12327624 | X33: =W33+X32 -> 14027624
A34: Average ARR | M34: 35000 | N34: 35000 | O34: 35000 | P34: 35000 | Q34: 35000 | R34: 35000 | S34: 45000 | T34: 45000 | U34: 52373 | V34: 52373 | W34: 52373 | X34: 52373
A35: Pipeline Cover | M35: 2 | N35: 2 | O35: 2 | P35: 2 | Q35: 2 | R35: 3 | S35: 3 | T35: 3 | U35: 4.5 | V35: 3.5 | W35: 4.5 | X35: 3.5
A36: Opps Required | M36: - | N36: - | O36: - | P36: - | Q36: =(Q32/Q34)*Q35 -> 33.257143 | R36: =(R32/R34)*R35 -> 64.2 | S36: =(S32/S34)*S35 -> 80.266667 | T36: =(T32/T34)*T35 -> 116.66667 | U36: =(U32/U34)*U35 -> 118.14294 | V36: =(V32/V34)*V35 -> 113.60816 | W36: =(W32/W34)*W35 -> 146.06763 | X36: =(X32/X34)*X35 -> 113.60816
A37: Delta Opps | M37: - | N37: - | O37: - | P37: - | Q37: =Q36-Q31 -> -29.432857 | R37: =R36-R31 -> -6.14 | S37: =S36-S31 -> -0.73333333 | T37: =T36-T31 -> 30.156667 | U37: =U36-U31 -> 29.103621 | V37: =V36-V31 -> 26.922258 | W37: =W36-W31 -> 62.350387 | X37: =X36-X31 -> 40.237333
A38: Operating % | M38: -% | N38: -% | O38: -% | P38: -% | Q38: =Q31/Q36 -> 1.8850086 | R38: =R31/R36 -> 1.0956386 | S38: =S31/S36 -> 1.0091362 | T38: =T31/T36 -> 0.74151429 | U38: =U31/U36 -> 0.75365754 | V38: =V31/V36 -> 0.76302531 | W38: =W31/W36 -> 0.57314029 | X38: =X31/X36 -> 0.64582355
A39: Resulting Bookings | U39: =U38*U32 -> 1036279.1 | V39: =V38*V32 -> 1297143 | W39: =W38*W32 -> 974338.49 | X39: =X38*X32 -> 1097900
A40: Closing CARR | J40: 6450000 | U40: =6500000+U39-120000 -> 7416279.1 | V40: =U40+V39-120000 -> 8593422.1 | W40: =V40+W39-120000 -> 9447760.6 | X40: =W40+X39-120000 -> 10425661

Sheet Sheet5
A1: Probability | B1: Q1 23 | C1: Q2 23 | D1: Q3 23 | E1: Q4 23 | F1: Q1 23 | G1: Q2 23 | H1: Q3 23 | I1: Q4 23
A2: Q2 22 | F2: 0.08
A3: Q3 22 | B3: 0.01 | F3: 0.36 | G3: 0.08
A4: Q4 22 | B4: 0.1 | C4: 0.01 | F4: 0.43 | G4: 0.36 | H4: 0.08
A5: Q1 23 | B5: =227/255 -> 0.89019608 | C5: 0.1 | D5: 0.01 | F5: 0.13 | G5: 0.43 | H5: 0.36 | I5: 0.08
A6: Q2 23 | C6: =227/255 -> 0.89019608 | D6: 0.1 | E6: 0.01 | G6: 0.13 | H6: 0.43 | I6: 0.36
A7: Q3 23 | D7: =227/255 -> 0.89019608 | E7: 0.1 | H7: 0.13 | I7: 0.43
A8: Q4 23 | E8: 0.89 | I8: 0.13

Sheet Sheet6
B1: SQLs | C1: Q2 22 | D1: Q3 22 | E1: Q4 22 | F1: Q1 23 | G1: Q2 23 | H1: Q3 23 | I1: Q4 23 | J1: Opps | K1: Marketing Opps | L1: Budget () | M1: Q1 21 | N1: Q2 21 | O1: Q3 21 | P1: Q4 21 | Q1: Q1 22 | R1: Q2 22 | S1: Q3 22 | T1: Q4 22 | U1: Q1 23 | V1: Q2 23 | W1: Q3 23 | X1: Q4 23
A2: Q3 22 | B2: 190 | D2: =$B2*Sheet5!D5 -> 1.9 | E2: =$B2*Sheet5!E5 -> 0 | F2: =$B2*Sheet5!F5 -> 24.7 | J2: 85 | K2: =J2*0.75 -> 63.75 | L2: 1038700 | S2: =$J2*Sheet5!S5 -> 0 | T2: =$J2*Sheet5!T5 -> 0 | U2: =$J2*Sheet5!U5 -> 0 | V2: =$J2*Sheet5!V5 -> 0
A3: Q4 22 | B3: 144 | E3: =$B3*Sheet5!E6 -> 1.44 | F3: =$B3*Sheet5!F6 -> 0 | G3: =$B3*Sheet5!G6 -> 18.72 | J3: 84 | K3: =J3*0.75 -> 63 | L3: 834200 | T3: =$J3*Sheet5!T6 -> 0 | U3: =$J3*Sheet5!U6 -> 0 | V3: =$J3*Sheet5!V6 -> 0 | W3: =$J3*Sheet5!W6 -> 0
A4: Q1 23 | B4: 147 | F4: =$B4*Sheet5!F7 -> 0 | G4: =$B4*Sheet5!G7 -> 0 | H4: =$B4*Sheet5!H7 -> 19.11 | J4: =(50/(31+28+7))*(31+28+31) -> 68.181818 | K4: =J4*0.75 -> 51.136364 | L4: 645203 | U4: =$J4*Sheet5!U7 -> 0 | V4: =$J4*Sheet5!V7 -> 0 | W4: =$J4*Sheet5!W7 -> 0 | X4: =$J4*Sheet5!X7 -> 0
A5: Q2 23 | B5: 147 | G5: =$B5*Sheet5!G8 -> 0 | H5: =$B5*Sheet5!H8 -> 0 | I5: =$B5*Sheet5!I8 -> 19.11 | J5: =G10 -> 9.5021258 | K5: =J5*0.75 -> 7.1265944 | L5: 677625 | V5: =$J5*Sheet5!V8 -> 0 | W5: =$J5*Sheet5!W8 -> 0 | X5: =$J5*Sheet5!X8 -> 0
A6: Q3 23 | B6: 147 | H6: =$B6*Sheet5!H9 -> 0 | I6: =$B6*Sheet5!I9 -> 0 | J6: =H10 -> 9.7000868 | K6: =J6*0.75 -> 7.2750651 | L6: 677625 | W6: =$J6*Sheet5!W9 -> 0 | X6: =$J6*Sheet5!X9 -> 0
A7: Q4 23 | B7: 147 | I7: =$B7*Sheet5!I10 -> 0 | J7: =I10 -> 9.7000868 | K7: =J7*0.75 -> 7.2750651 | L7: 677625 | X7: =$J7*Sheet5!X10 -> 0
A8: Total SQLs | C8: =sum(C2:C7) -> 0 | D8: =sum(D2:D7) -> 1.9 | E8: =sum(E2:E7) -> 1.44 | F8: =sum(F2:F7) -> 24.7 | G8: =sum(G2:G7) -> 18.72 | H8: =sum(H2:H7) -> 19.11 | I8: =sum(I2:I7) -> 19.11
A9: Conversion | C9: =0.5 -> 0.5 | D9: =0.5 -> 0.5 | E9: =0.5 -> 0.5 | F9: =234/461 -> 0.50759219 | G9: =234/461 -> 0.50759219 | H9: =234/461 -> 0.50759219 | I9: =234/461 -> 0.50759219
A10: Forecasted Opps | C10: =C8*C9 -> 0 | D10: =D8*D9 -> 0.95 | E10: =E8*E9 -> 0.72 | F10: =F8*F9 -> 12.537527 | G10: =G8*G9 -> 9.5021258 | H10: =H8*H9 -> 9.7000868 | I10: =I8*I9 -> 9.7000868
A11: Delta to Actual | F11: =F10-J4 -> -55.644291 | G11: =G10-J5 -> 0 | H11: =H10-J6 -> 0 | I11: =I10-J7 -> 0
A12: Total Opps | M12: =sum(M2:M7) -> 0 | N12: =sum(N2:N7) -> 0 | O12: =sum(O2:O7) -> 0 | P12: =sum(P2:P7) -> 0 | Q12: =sum(Q2:Q7) -> 0 | R12: =sum(R2:R7) -> 0 | S12: =sum(S2:S7) -> 0 | T12: =sum(T2:T7) -> 0 | ... X12: =sum(X2:X7) -> 0
A13: Base Target | M13: - | N13: - | O13: - | P13: - | Q13: 582000 | R13: 749000 | S13: 1204000 | T13: 1750000 | U13: 1375000 | V13: 1700000 | W13: =V13 -> 1700000 | X13: =W13 -> 1700000
A14: ARR | M14: - | N14: - | O14: - | P14: - | Q14: =3267624+Q13 -> 3849624 | R14: =Q14+R13 -> 4598624 | S14: =R14+S13 -> 5802624 | T14: =S14+T13 -> 7552624 | U14: =T14+U13 -> 8927624 | V14: =U14+V13 -> 10627624 | W14: =V14+W13 -> 12327624 | X14: =W14+X13 -> 14027624
A15: Average ARR | M15: 35000 | N15: 35000 | O15: 35000 | P15: 35000 | Q15: 35000 | R15: 35000 | S15: 45000 | T15: 45000 | U15: 52373 | V15: 50000 | W15: 50000 | X15: 50000
A16: Pipeline Cover | M16: 2 | N16: 2 | O16: 2 | P16: 2 | Q16: 2 | R16: 3 | S16: 3 | T16: 3 | U16: 4.5 | V16: 3.5 | W16: 4.5 | X16: 3.5
A17: Opps Required | M17: - | N17: - | O17: - | P17: - | Q17: =(Q13/Q15)*Q16 -> 33.257143 | R17: =(R13/R15)*R16 -> 64.2 | S17: =(S13/S15)*S16 -> 80.266667 | T17: =(T13/T15)*T16 -> 116.66667 | U17: =(U13/U15)*U16 -> 118.14294 | V17: =(V13/V15)*V16 -> 119 | W17: =(W13/W15)*W16 -> 153 | X17: =(X13/X15)*X16 -> 119
A18: Delta Opps | M18: - | N18: - | O18: - | P18: - | Q18: =Q17-Q12 -> 33.257143 | R18: =R17-R12 -> 64.2 | S18: =S17-S12 -> 80.266667 | T18: =T17-T12 -> 116.66667 | U18: =U17-U12 -> 118.14294 | V18: =V17-V12 -> 119 | W18: =W17-W12 -> 153 | X18: =X17-X12 -> 119
A19: Operating % | M19: -% | N19: -% | O19: -% | P19: -% | Q19: =Q12/Q17 -> 0 | R19: =R12/R17 -> 0 | S19: =S12/S17 -> 0 | T19: =T12/T17 -> 0 | U19: =U12/U17 -> 0 | V19: =V12/V17 -> 0 | W19: =W12/W17 -> 0 | X19: =X12/X17 -> 0
A20: Resulting Bookings | U20: =U19*U13 -> 0 | V20: =V19*V13 -> 0 | W20: =W19*W13 -> 0 | X20: =X19*X13 -> 0
A21: Closing ARR | J21: 6450000 | U21: =6500000+U20-120000 -> 6380000 | V21: =U21+V20-120000 -> 6260000 | W21: =V21+W20-120000 -> 6140000 | X21: =W21+X20-120000 -> 6020000

Sheet 2023-TO BE
A1: Probability | C1: Q2 22 | D1: Q3 22 | E1: Q4 22 | F1: Q1 23 | G1: Q2 23 | H1: Q3 23 | I1: Q4 23 | J1: NA | M1: Q1 21 | N1: Q2 21 | O1: Q3 21 | P1: Q4 21 | Q1: Q1 22 | R1: Q2 22 | S1: Q3 22 | T1: Q4 22 | U1: Q1 23 | V1: Q2 23 | W1: Q3 23 | X1: Q4 23 | Y1: Average marketing cost per opp ()
A2: Q1 21 | M2: 0.13 | N2: 0.43 | O2: 0.36 | P2: 0.08
A3: Q2 21 | N3: 0.13 | O3: 0.43 | P3: 0.36 | Q3: 0.08
A4: Q3 21 | O4: 0.13 | P4: 0.43 | Q4: 0.36 | R4: 0.08
A5: Q4 21 | P5: 0.13 | Q5: 0.43 | R5: 0.36 | S5: 0.08
A6: Q1 22 | C6: =227/255 -> 0.89019608 | Q6: 0.13 | R6: 0.43 | S6: 0.36 | T6: 0.08
A7: Q2 22 | C7: =25/255 -> 0.098039216 | D7: =227/255 -> 0.89019608 | R7: 0.13 | S7: 0.43 | T7: 0.36 | U7: 0.11
A8: Q3 22 | C8: =3/255 -> 0.011764706 | D8: =25/255 -> 0.098039216 | E8: =227/255 -> 0.89019608 | F8: 0.01 | S8: 0.13 | T8: 0.43 | U8: 0.26 | V8: 0.11
A9: Q4 22 | D9: =3/255 -> 0.011764706 | E9: =25/255 -> 0.098039216 | F9: 0.1 | G9: 0.01 | T9: 0.13 | U9: 0.4 | V9: 0.26 | W9: 0.11
A10: Q1 23 | E10: =3/255 -> 0.011764706 | F10: =227/255 -> 0.89019608 | G10: 0.1 | H10: 0.01 | U10: 0.23 | V10: 0.4 | W10: 0.26 | X10: 0.11
A11: Q2 23 | G11: =227/255 -> 0.89019608 | H11: 0.1 | I11: 0.01 | V11: 0.23 | W11: 0.4 | X11: 0.26
A12: Q3 23 | H12: =227/255 -> 0.89019608 | I12: 0.1 | W12: 0.23 | X12: 0.4
A13: Q4 23 | I13: 0.89 | X13: 0.13
B14: SQLs | C14: Q2 22 | D14: Q3 22 | E14: Q4 22 | F14: Q1 23 | G14: Q2 23 | H14: Q3 23 | I14: Q4 23 | J14: Opps | K14: Marketing Opps | L14: Budget () | M14: Q1 21 | N14: Q2 21 | O14: Q3 21 | P14: Q4 21 | Q14: Q1 22 | R14: Q2 22 | S14: Q3 22 | T14: Q4 22 | U14: Q1 23 | V14: Q2 23 | W14: Q3 23 | X14: Q4 23 | Z14: QC Required
A15: Q1 21 | J15: 29 | M15: =$J15*M2 -> 3.77 | N15: =$J15*N2 -> 12.47 | O15: =$J15*O2 -> 10.44 | P15: =$J15*P2 -> 2.32
A16: Q2 21 | J16: =15+11+6 -> 32 | N16: =$J16*N3 -> 4.16 | O16: =$J16*O3 -> 13.76 | P16: =$J16*P3 -> 11.52 | Q16: =$J16*Q3 -> 2.56
A17: Q3 21 | J17: =30+19+20 -> 69 | O17: =$J17*O4 -> 8.97 | P17: =$J17*P4 -> 29.67 | Q17: =$J17*Q4 -> 24.84 | R17: =$J17*R4 -> 5.52
A18: Q4 21 | J18: =16+28+16 -> 60 | P18: =$J18*P5 -> 7.8 | Q18: =$J18*Q5 -> 25.8 | R18: =$J18*R5 -> 21.6 | S18: =$J18*S5 -> 4.8
A19: Q1 22 | B19: 56 | C19: =$B19*C6 -> 49.85098 | J19: =16+23+34 -> 73 | L19: 657933 | Q19: =$J19*Q6 -> 9.49 | R19: =$J19*R6 -> 31.39 | S19: =$J19*S6 -> 26.28 | T19: =$J19*T6 -> 5.84
A20: Q2 22 | B20: 128 | C20: =$B20*C7 -> 12.54902 | D20: =$B20*D7 -> 113.9451 | J20: 91 | L20: 852976 | R20: =$J20*R7 -> 11.83 | S20: =$J20*S7 -> 39.13 | T20: =$J20*T7 -> 32.76 | U20: =$J20*U7 -> 10.01
A21: Q3 22 | B21: 190 | C21: =$B21*C8 -> 2.2352941 | D21: =$B21*D8 -> 18.627451 | E21: =$B21*E8 -> 169.13725 | F21: =$B21*F8 -> 1.9 | J21: 83 | K21: =J21*0.75 -> 62.25 | L21: 1038700 | S21: =$J21*S8 -> 10.79 | T21: =$J21*T8 -> 35.69 | U21: =$J21*U8 -> 21.58 | V21: =$J21*V8 -> 9.13 | Y21: =L21/K21 -> 16685.944 | Z21: =J21/15 -> 5.5333333
A22: Q4 22 | B22: 144 | D22: =$B22*D9 -> 1.6941176 | E22: =$B22*E9 -> 14.117647 | F22: =$B22*F9 -> 14.4 | G22: =$B22*G9 -> 1.44 | J22: 94 | K22: =J22*0.75 -> 70.5 | L22: 834200 | T22: =$J22*T9 -> 12.22 | U22: =$J22*U9 -> 37.6 | V22: =$J22*V9 -> 24.44 | W22: =$J22*W9 -> 10.34 | Y22: =L22/K22 -> 11832.624 | Z22: =J22/15 -> 6.2666667
A23: Q1 23 | B23: 147 | E23: =$B23*E10 -> 1.7294118 | F23: =$B23*F10 -> 130.85882 | G23: =$B23*G10 -> 14.7 | H23: =$B23*H10 -> 1.47 | J23: =(70/(31+28+14))*(31+28+31) -> 86.30137 | K23: =J23*0.75 -> 64.726027 | L23: 645203 | U23: =$J23*U10 -> 19.849315 | V23: =$J23*V10 -> 34.520548 | W23: =$J23*W10 -> 22.438356 | X23: =$J23*X10 -> 9.4931507 | Y23: =L23/K23 -> 9968.2157 | Z23: =J23/15 -> 5.7534247
A24: Q2 23 | B24: 200 | G24: =$B24*G11 -> 178.03922 | H24: =$B24*H11 -> 20 | I24: =$B24*I11 -> 2 | J24: =G29 -> 106.79857 | K24: =J24*0.75 -> 80.098926 | L24: 677625 | V24: =$J24*V11 -> 24.563671 | W24: =$J24*W11 -> 42.719427 | X24: =$J24*X11 -> 27.767628 | Y24: =L24/K24 -> 8459.8512 | Z24: =J24/15 -> 7.1199046
A25: Q3 23 | B25: 200 | H25: =$B25*H12 -> 178.03922 | I25: =$B25*I12 -> 20 | J25: =H29 -> 109.73007 | K25: =J25*0.75 -> 82.297551 | L25: 677625 | W25: =$J25*W12 -> 25.237916 | X25: =$J25*X12 -> 43.892027 | Y25: =L25/K25 -> 8233.8416 | Z25: =J25/15 -> 7.3153379
A26: Q4 23 | B26: 165 | I26: =$B26*I13 -> 146.85 | J26: =I29 -> 92.8675 | K26: =J26*0.75 -> 69.650625 | L26: 677625 | X26: =$J26*X13 -> 12.072775 | Y26: =L26/K26 -> 9728.9149 | Z26: =J26/15 -> 6.1911667
A27: Total SQLs | C27: =sum(C19:C26) -> 64.635294 | D27: =sum(D19:D26) -> 134.26667 | E27: =sum(E19:E26) -> 184.98431 | F27: =sum(F19:F26) -> 147.15882 | G27: =sum(G19:G26) -> 194.17922 | H27: =sum(H19:H26) -> 199.50922 | I27: =sum(I19:I26) -> 168.85
A28: Conversion | C28: =0.5 -> 0.5 | D28: =0.5 -> 0.5 | E28: =0.5 -> 0.5 | F28: 0.55 | G28: 0.55 | H28: 0.55 | I28: 0.55
A29: Forecasted Opps | C29: =C27*C28 -> 32.317647 | D29: =D27*D28 -> 67.133333 | E29: =E27*E28 -> 92.492157 | F29: =F27*F28 -> 80.937353 | G29: =G27*G28 -> 106.79857 | H29: =H27*H28 -> 109.73007 | I29: =I27*I28 -> 92.8675
A30: Delta to Actual | F30: =F29-J23 -> -5.3640169 | G30: =G29-J24 -> 0 | H30: =H29-J25 -> 0 | I30: =I29-J26 -> 0
A31: Total Opps | M31: =sum(M15:M26) -> 3.77 | N31: =sum(N15:N26) -> 16.63 | O31: =sum(O15:O26) -> 33.17 | P31: =sum(P15:P26) -> 51.31 | Q31: =sum(Q15:Q26) -> 62.69 | R31: =sum(R15:R26) -> 70.34 | S31: =sum(S15:S26) -> 81 | T31: =sum(T15:T26) -> 86.51 | ... X31: =sum(X15:X26) -> 93.225581
A32: Base Target | M32: - | N32: - | O32: - | P32: - | Q32: 582000 | R32: 749000 | S32: 1204000 | T32: 1750000 | U32: 1375000 | V32: 1700000 | W32: =V32 -> 1700000 | X32: =W32 -> 1700000
A33: ARR | M33: - | N33: - | O33: - | P33: - | Q33: =3267624+Q32 -> 3849624 | R33: =Q33+R32 -> 4598624 | S33: =R33+S32 -> 5802624 | T33: =S33+T32 -> 7552624 | U33: =T33+U32 -> 8927624 | V33: =U33+V32 -> 10627624 | W33: =V33+W32 -> 12327624 | X33: =W33+X32 -> 14027624
A34: Average ARR | M34: 35000 | N34: 35000 | O34: 35000 | P34: 35000 | Q34: 35000 | R34: 35000 | S34: 45000 | T34: 45000 | U34: 52373 | V34: 55000 | W34: 60000 | X34: 60000
A35: Pipeline Cover | M35: 2 | N35: 2 | O35: 2 | P35: 2 | Q35: 2 | R35: 3 | S35: 3 | T35: 3 | U35: 4.5 | V35: 3.5 | W35: 4.5 | X35: 3.5
A36: Opps Required | M36: - | N36: - | O36: - | P36: - | Q36: =(Q32/Q34)*Q35 -> 33.257143 | R36: =(R32/R34)*R35 -> 64.2 | S36: =(S32/S34)*S35 -> 80.266667 | T36: =(T32/T34)*T35 -> 116.66667 | U36: =(U32/U34)*U35 -> 118.14294 | V36: =(V32/V34)*V35 -> 108.18182 | W36: =(W32/W34)*W35 -> 127.5 | X36: =(X32/X34)*X35 -> 99.166667
A37: Delta Opps | M37: - | N37: - | O37: - | P37: - | Q37: =Q36-Q31 -> -29.432857 | R37: =R36-R31 -> -6.14 | S37: =S36-S31 -> -0.73333333 | T37: =T36-T31 -> 30.156667 | U37: =U36-U31 -> 29.103621 | V37: =V36-V31 -> 15.527599 | W37: =W36-W31 -> 26.764301 | X37: =X36-X31 -> 5.9410857
A38: Operating % | M38: -% | N38: -% | O38: -% | P38: -% | Q38: =Q31/Q36 -> 1.8850086 | R38: =R31/R36 -> 1.0956386 | S38: =S31/S36 -> 1.0091362 | T38: =T31/T36 -> 0.74151429 | U38: =U31/U36 -> 0.75365754 | V38: =V31/V36 -> 0.85646757 | W38: =W31/W36 -> 0.79008392 | X38: =X31/X36 -> 0.94008989
A39: Resulting Bookings | U39: =U38*U32 -> 1036279.1 | V39: =V38*V32 -> 1455994.9 | W39: =W38*W32 -> 1343142.7 | X39: =X38*X32 -> 1598152.8
A40: Closing ARR | J40: 6455827 | U40: =J40+U39-120000 -> 7372106.1 | V40: =U40+V39-120000 -> 8708101 | W40: =V40+W39-120000 -> 9931243.6 | X40: =W40+X39-120000 -> 11409396

Sheet Overall Performance
C1: Q1 21 | D1: Q2 21 | E1: Q3 21 | F1: Q4 21 | G1: Q1 22 | H1: Q2 22 | I1: Q3 22 | J1: Q4 22 | K1: Q1 23 | L1: Q2 23 | M1: Q3 23 | N1: Q4 23 | O1: Q1 24 | P1: Q2 24 | Q1: Q3 24 | R1: Q4 24 | S1: Q1 25 | T1: Q2 25 | U1: Q3 25 | V1: Q4 25 | W1: Q1 26 | X1: Q2 26 | Y1: Q3 26 | Z1: Q4 26 | AA1: Q1 27 | AB1: Q2 27 | AC1: Q3 27 | AD1: Q4 27 | AE1: Q1 28 | AF1: Q2 28 | AG1: Q3 28 | AH1: Q4 28
A2: NORAM | B2: Inbound SQLs | R2: {=TRANSPOSE('Inbound Cascade NORAM'!$B$50:$B$66)} -> 24 | S2: 24 | T2: 31 | U2: #REF! | V2: #REF! | W2: #REF! | X2: #REF! | Y2: #REF! | Z2: #REF! | AA2: #REF! | AB2: #REF! | AC2: #REF! | AD2: #REF! | AE2: #REF! | AF2: #REF! | AG2: #REF! | AH2: #REF!
B3: Outbound SQLs | R3: {=TRANSPOSE('Outbound Cascade NORAM'!$B$50:$B$66)} -> 10 | S3: 23 | T3: 9 | U3: 0 | V3: 0 | W3: 0 | X3: 0 | Y3: 0 | Z3: 0 | AA3: 0 | AB3: 0 | AC3: 0 | AD3: 0 | AE3: 0 | AF3: 0 | AG3: 0 | AH3: 0
B4: ILO SQLs | R4: {=TRANSPOSE('ILO Cascade NORAM'!$B$50:$B$66)} -> 20 | S4: 26 | T4: 23 | U4: 24.5 | V4: 31.85 | W4: 31.85 | X4: 36.75 | Y4: 36.75 | Z4: 41.65 | AA4: 41.65 | AB4: 41.65 | AC4: 41.65 | AD4: 41.65 | AE4: 41.65 | AF4: 41.65 | AG4: 41.65 | AH4: 41.65
B5: Event SQLs | R5: {=TRANSPOSE('Events Cascade NORAM'!$B$50:$B$66)} -> 26 | S5: 10 | T5: 10 | U5: 15 | V5: 15 | W5: 15 | X5: 15 | Y5: 15 | Z5: 15 | AA5: 15 | AB5: 15 | AC5: 15 | AD5: 15 | AE5: 15 | AF5: 15 | AG5: 15 | AH5: 15
B6: Total SQLs | R6: =sum(R2:R5) -> 80 | S6: =sum(S2:S5) -> 83 | T6: =sum(T2:T5) -> 73 | U6: =sum(U2:U5) -> #REF! | V6: =sum(V2:V5) -> #REF! | W6: =sum(W2:W5) -> #REF! | X6: =sum(X2:X5) -> #REF! | Y6: =sum(Y2:Y5) -> #REF! | ... AH6: =sum(AH2:AH5) -> #REF!
B7: Outbound Opps | C7: ='Outbound Cascade EMESA NORTH'!AG64 | D7: ='Outbound Cascade EMESA NORTH'!AH64 | E7: ='Outbound Cascade EMESA NORTH'!AI64 | F7: ='Outbound Cascade EMESA NORTH'!AJ64 | G7: ='Outbound Cascade EMESA NORTH'!AK64 | H7: ='Outbound Cascade EMESA NORTH'!AL64 | I7: ='Outbound Cascade EMESA NORTH'!AM64 | J7: ='Outbound Cascade EMESA NORTH'!AN64 | K7: ='Outbound Cascade EMESA NORTH'!G67/2 -> 0.33382353 | L7: ='Outbound Cascade EMESA NORTH'!H67/2 -> 0.37132353 | M7: ='Outbound Cascade EMESA NORTH'!I67/2 -> 0.37507353 | N7: ='Outbound Cascade EMESA NORTH'!J67/2 -> 0.37507353 | O7: ='Outbound Cascade EMESA NORTH'!K67/2 -> 0.37507353 | P7: ='Outbound Cascade EMESA NORTH'!L67/2 -> 0.37507353 | Q7: ='Outbound Cascade EMESA NORTH'!M67/2 -> 0.37507353 | R7: ='Outbound Cascade NORAM'!N67 -> 1.5 | S7: ='Outbound Cascade NORAM'!O67 -> 3.2355 | T7: ='Outbound Cascade NORAM'!P67 -> 1.5615 | U7: ='Outbound Cascade NORAM'!Q67 -> 0.1695 | V7: ='Outbound Cascade NORAM'!R67 -> 0.0135 | W7: ='Outbound Cascade NORAM'!S67 -> 0 | X7: ='Outbound Cascade NORAM'!T67 -> 0 | Y7: ='Outbound Cascade NORAM'!U67 -> 0 | ... AH7: ='Outbound Cascade NORAM'!AD67 -> 0
B8: ILO Opps | R8: ='ILO Cascade NORAM'!N67 -> 7.56 | S8: ='ILO Cascade NORAM'!O67 -> 10.096 | T8: ='ILO Cascade NORAM'!P67 -> 9.308 | U8: ='ILO Cascade NORAM'!Q67 -> 9.746 | V8: ='ILO Cascade NORAM'!R67 -> 13.827925 | W8: ='ILO Cascade NORAM'!S67 -> 14.289985 | X8: ='ILO Cascade NORAM'!T67 -> 16.298193 | Y8: ='ILO Cascade NORAM'!U67 -> 16.518693 | ... AH8: ='ILO Cascade NORAM'!AD67 -> 18.7425
B9: Inbound Opps | K9: ='Inbound Cascade NORAM'!G67 -> 14.514541 | L9: ='Inbound Cascade NORAM'!H67 -> 11.006071 | M9: ='Inbound Cascade NORAM'!I67 -> 11.461059 | N9: ='Inbound Cascade NORAM'!J67 -> 9.3761882 | O9: ='Inbound Cascade NORAM'!K67 -> 8.5048471 | P9: ='Inbound Cascade NORAM'!L67 -> 7.7679059 | Q9: ='Inbound Cascade NORAM'!M67 -> 11.534353 | R9: ='Inbound Cascade NORAM'!N67 -> 11.9568 | ... AH9: ='Inbound Cascade NORAM'!AD67 -> #REF!
B10: Event Opps | K10: ='Events Cascade EMESA'!G67/2 -> 0 | L10: ='Events Cascade EMESA'!H67/2 -> 0 | M10: ='Events Cascade EMESA'!I67/2 -> 0 | N10: ='Events Cascade EMESA'!J67/2 -> 0 | O10: ='Events Cascade EMESA'!K67/2 -> 0 | P10: ='Events Cascade EMESA'!L67/2 -> 0 | Q10: ='Events Cascade EMESA'!M67/2 -> 0 | R10: ='Events Cascade NORAM'!N67 -> 3.471 | S10: ='Events Cascade NORAM'!O67 -> 1.725 | T10: ='Events Cascade NORAM'!P67 -> 1.524 | U10: ='Events Cascade NORAM'!Q67 -> 2.1675 | V10: ='Events Cascade NORAM'!R67 -> 2.2425 | W10: ='Events Cascade NORAM'!S67 -> 2.2504412 | X10: ='Events Cascade NORAM'!T67 -> 2.2504412 | Y10: ='Events Cascade NORAM'!U67 -> 2.2504412 | ... AH10: ='Events Cascade NORAM'!AD67 -> 2.25
B11: Partner Opps | K11: ='Partner Cascade NORAM'!G67 -> 0 | L11: ='Partner Cascade NORAM'!H67 -> 3 | M11: ='Partner Cascade NORAM'!I67 -> 2 | N11: ='Partner Cascade NORAM'!J67 -> 4 | O11: ='Partner Cascade NORAM'!K67 -> 0 | P11: ='Partner Cascade NORAM'!L67 -> 1 | Q11: ='Partner Cascade NORAM'!M67 -> 0 | R11: ='Partner Cascade NORAM'!N67 -> 0 | ... AH11: ='Partner Cascade NORAM'!AD67 -> 6.7565748
A12: TOTAL NORAM OCR | C12: =SUM(#REF!) -> #REF! | D12: =SUM(#REF!) -> #REF! | E12: =SUM(#REF!) -> #REF! | F12: =SUM(#REF!) -> #REF! | G12: =SUM(#REF!) -> #REF! | H12: =SUM(#REF!) -> #REF! | I12: =SUM(#REF!) -> #REF! | J12: =SUM(#REF!) -> #REF! | K12: =SUM(K7:K11) -> 14.848365 | L12: =SUM(L7:L11) -> 14.377394 | M12: =SUM(M7:M11) -> 13.836132 | N12: =SUM(N7:N11) -> 13.751262 | O12: =SUM(O7:O11) -> 8.8799206 | P12: =SUM(P7:P11) -> 9.1429794 | Q12: =SUM(Q7:Q11) -> 11.909426 | R12: =SUM(R7:R11) -> 24.4878 | ... AH12: =SUM(AH7:AH11) -> #REF!
A13: EMESA N | B13: Inbound SQLs | R13: {=TRANSPOSE('Inbound Cascade EMESA NORTH'!$B$50:$B$66)} -> 18 | S13: 18 | T13: 18 | U13: #REF! | V13: #REF! | W13: #REF! | X13: #REF! | Y13: #REF! | Z13: #REF! | AA13: #REF! | AB13: #REF! | AC13: #REF! | AD13: #REF! | AE13: #REF! | AF13: #REF! | AG13: #REF! | AH13: #REF!
B14: Outbound SQLs | R14: {=TRANSPOSE('Outbound Cascade EMESA NORTH'!$B$50:$B$66)} -> 7 | S14: 12 | T14: 5 | U14: 0 | V14: 0 | W14: 0 | X14: 0 | Y14: 0 | Z14: 0 | AA14: 0 | AB14: 0 | AC14: 0 | AD14: 0 | AE14: 0 | AF14: 0 | AG14: 0 | AH14: 0
B15: ILO SQLs | R15: {=TRANSPOSE('ILO Cascade EMESA NORTH'!$B$50:$B$66)} -> 25 | S15: 23 | T15: 40 | U15: 31.5 | V15: 40.95 | W15: 40.95 | X15: 47.25 | Y15: 47.25 | Z15: 53.55 | AA15: 53.55 | AB15: 53.55 | AC15: 53.55 | AD15: 53.55 | AE15: 53.55 | AF15: 53.55 | AG15: 53.55 | AH15: 53.55
B16: Event SQLs | R16: {=TRANSPOSE('Events Cascade EMESA'!$B$50:$B$66)} -> 26 | S16: 10 | T16: 10 | U16: 15 | V16: 15 | W16: 15 | X16: 15 | Y16: 15 | Z16: 15 | AA16: 15 | AB16: 15 | AC16: 15 | AD16: 15 | AE16: 15 | AF16: 15 | AG16: 15 | AH16: 15
B17: Event SQLs | R17: =R16/2 -> 13 | S17: =S16/2 -> 5 | T17: =T16/2 -> 5 | U17: =U16/2 -> 7.5 | V17: =V16/2 -> 7.5 | W17: =W16/2 -> 7.5 | X17: =X16/2 -> 7.5 | Y17: =Y16/2 -> 7.5 | ... AH17: =AH16/2 -> 7.5
B18: TOTAL SQLs | R18: =sum(R13:R16) -> 76 | S18: =sum(S13:S15,S17) -> 58 | T18: =sum(T13:T15,T17) -> 68 | U18: =sum(U13:U15,U17) -> #REF! | V18: =sum(V13:V15,V17) -> #REF! | W18: =sum(W13:W15,W17) -> #REF! | X18: =sum(X13:X15,X17) -> #REF! | Y18: =sum(Y13:Y15,Y17) -> #REF! | Z18: =sum(Z13:Z15,Z17) -> #REF! | ... AH18: =sum(AH13:AH15,AH17) -> #REF!
B19: Outbound Opps | O19: ='Outbound Cascade EMESA NORTH'!K67/2 -> 0.37507353 | P19: ='Outbound Cascade EMESA NORTH'!L67/2 -> 0.37507353 | Q19: ='Outbound Cascade EMESA NORTH'!M67/2 -> 0.37507353 | R19: ='Outbound Cascade EMESA NORTH'!N67 -> 1.017 | S19: ='Outbound Cascade EMESA NORTH'!O67 -> 1.7145 | T19: ='Outbound Cascade EMESA NORTH'!P67 -> 0.858 | U19: ='Outbound Cascade EMESA NORTH'!Q67 -> 0.093 | V19: ='Outbound Cascade EMESA NORTH'!R67 -> 0.0075 | W19: ='Outbound Cascade EMESA NORTH'!S67 -> 0 | X19: ='Outbound Cascade EMESA NORTH'!T67 -> 0 | Y19: ='Outbound Cascade EMESA NORTH'!U67 -> 0 | ... AH19: ='Outbound Cascade EMESA NORTH'!AD67 -> 0
B20: ILO Opps | R20: ='ILO Cascade EMESA NORTH'!N67 -> 11.2625 | S20: ='ILO Cascade EMESA NORTH'!O67 -> 10.449 | T20: ='ILO Cascade EMESA NORTH'!P67 -> 17.1675 | U20: ='ILO Cascade EMESA NORTH'!Q67 -> 14.51925 | V20: ='ILO Cascade EMESA NORTH'!R67 -> 17.997975 | W20: ='ILO Cascade EMESA NORTH'!S67 -> 18.388588 | X20: ='ILO Cascade EMESA NORTH'!T67 -> 20.954819 | Y20: ='ILO Cascade EMESA NORTH'!U67 -> 21.238319 | ... AH20: ='ILO Cascade EMESA NORTH'!AD67 -> 24.0975
B21: Inbound Opps | O21: ='Inbound Cascade EMESA NORTH'!K67 -> 10.577118 | P21: ='Inbound Cascade EMESA NORTH'!L67 -> 10.139576 | Q21: ='Inbound Cascade EMESA NORTH'!M67 -> 9.6084706 | R21: ='Inbound Cascade EMESA NORTH'!N67 -> 9.0648 | S21: ='Inbound Cascade EMESA NORTH'!O67 -> 9.0054 | T21: ='Inbound Cascade EMESA NORTH'!P67 -> 9 | U21: ='Inbound Cascade EMESA NORTH'!Q67 -> #REF! | V21: ='Inbound Cascade EMESA NORTH'!R67 -> #REF! | ... AH21: ='Inbound Cascade EMESA NORTH'!AD67 -> #REF!
B22: Event Opps | O22: ='Events Cascade EMESA'!K67/2 -> 0 | P22: ='Events Cascade EMESA'!L67/2 -> 0 | Q22: ='Events Cascade EMESA'!M67/2 -> 0 | R22: ='Events Cascade EMESA'!N67/2 -> 1.7355 | S22: ='Events Cascade EMESA'!O67 -> 1.725 | T22: ='Events Cascade EMESA'!P67 -> 1.524 | U22: ='Events Cascade EMESA'!Q67 -> 2.1675 | V22: ='Events Cascade EMESA'!R67 -> 2.2425 | W22: ='Events Cascade EMESA'!S67 -> 2.2504412 | X22: ='Events Cascade EMESA'!T67 -> 2.2504412 | Y22: ='Events Cascade EMESA'!U67 -> 2.2504412 | Z22: ='Events Cascade EMESA'!V67 -> 2.2504412 | ... AH22: ='Events Cascade EMESA'!AD67 -> 2.25
B23: Partner Opps | O23: ='Partner Cascade EMESA NORTH'!K67 -> 7 | P23: ='Partner Cascade EMESA NORTH'!L67 -> 2 | Q23: ='Partner Cascade EMESA NORTH'!M67 -> 2 | R23: ='Partner Cascade EMESA NORTH'!N67 -> 0 | S23: ='Partner Cascade EMESA NORTH'!O67 -> 1 | T23: ='Partner Cascade EMESA NORTH'!P67 -> 1 | U23: ='Partner Cascade EMESA NORTH'!Q67 -> 2.1666667 | V23: ='Partner Cascade EMESA NORTH'!R67 -> 2.2316667 | ... AH23: ='Partner Cascade EMESA NORTH'!AD67 -> 5.0261409
A24: Total EMESA N OCR | O24: =sum(O19:O23) -> 17.952191 | P24: =sum(P19:P23) -> 12.51465 | Q24: =sum(Q19:Q23) -> 11.983544 | R24: =sum(R19:R23) -> 23.0798 | S24: =sum(S19:S23) -> 23.8939 | T24: =sum(T19:T23) -> 29.5495 | U24: =sum(U19:U23) -> #REF! | V24: =sum(V19:V23) -> #REF! | ... AH24: =sum(AH19:AH23) -> #REF!
A25: EMESA S | B25: Inbound SQLs | R25: {=TRANSPOSE('Inbound Cascade EMESA SOUTH'!$B$50:$B$66)} -> 18 | S25: 18 | T25: 24 | U25: #REF! | V25: #REF! | W25: #REF! | X25: #REF! | Y25: #REF! | Z25: #REF! | AA25: #REF! | AB25: #REF! | AC25: #REF! | AD25: #REF! | AE25: #REF! | AF25: #REF! | AG25: #REF! | AH25: #REF!
B26: Outbound SQLs | R26: {=TRANSPOSE('Outbound Cascade EMESA SOUTH'!$B$50:$B$66)} -> 4 | S26: 4 | T26: 1 | U26: 4 | V26: 0 | W26: 0 | X26: 0 | Y26: 0 | Z26: 0 | AA26: 0 | AB26: 0 | AC26: 0 | AD26: 0 | AE26: 0 | AF26: 0 | AG26: 0 | AH26: 0
B27: ILO SQLs | R27: {=TRANSPOSE('ILO Cascade EMESA SOUTH'!$B$50:$B$66)} -> 19 | S27: 19 | T27: 21 | U27: 20 | V27: 26 | W27: 26 | X27: 30 | Y27: 30 | Z27: 34 | AA27: 34 | AB27: 34 | AC27: 34 | AD27: 34 | AE27: 34 | AF27: 34 | AG27: 34 | AH27: 34
B28: Event SQLs | R28: {=TRANSPOSE('Events Cascade EMESA'!$B$50:$B$66)} -> 26 | S28: 10 | T28: 10 | U28: 15 | V28: 15 | W28: 15 | X28: 15 | Y28: 15 | Z28: 15 | AA28: 15 | AB28: 15 | AC28: 15 | AD28: 15 | AE28: 15 | AF28: 15 | AG28: 15 | AH28: 15
B29: Event SQLs | R29: =R28/2 -> 13 | S29: =S28/2 -> 5 | T29: =T28/2 -> 5 | U29: =U28/2 -> 7.5 | V29: =V28/2 -> 7.5 | W29: =W28/2 -> 7.5 | X29: =X28/2 -> 7.5 | Y29: =Y28/2 -> 7.5 | ... AH29: =AH28/2 -> 7.5
B30: TOTAL SQLs | R30: =sum(R25:R28) -> 67 | S30: =sum(S25:S27,S29) -> 46 | T30: =sum(T25:T27,T29) -> 51 | U30: =sum(U25:U27,U29) -> #REF! | V30: =sum(V25:V27,V29) -> #REF! | W30: =sum(W25:W27,W29) -> #REF! | X30: =sum(X25:X27,X29) -> #REF! | Y30: =sum(Y25:Y27,Y29) -> #REF! | Z30: =sum(Z25:Z27,Z29) -> #REF! | ... AH30: =sum(AH25:AH27,AH29) -> #REF!
B31: Outbound Opps | O31: ='Outbound Cascade EMESA NORTH'!K76/2 -> 0 | P31: ='Outbound Cascade EMESA NORTH'!L76/2 -> 0 | Q31: ='Outbound Cascade EMESA NORTH'!M76/2 -> 0 | R31: ='Outbound Cascade EMESA SOUTH'!N67 -> 0.6 | S31: ='Outbound Cascade EMESA SOUTH'!O67 -> 0.6 | T31: ='Outbound Cascade EMESA SOUTH'!P67 -> 0.1995 | U31: ='Outbound Cascade EMESA SOUTH'!Q67 -> 0.555 | V31: ='Outbound Cascade EMESA SOUTH'!R67 -> 0.0615 | W31: ='Outbound Cascade EMESA SOUTH'!S67 -> 0.006 | X31: ='Outbound Cascade EMESA SOUTH'!T67 -> 0 | Y31: ='Outbound Cascade EMESA SOUTH'!U67 -> 0 | ... AH31: ='Outbound Cascade EMESA SOUTH'!AD67 -> 0
B32: ILO Opps | R32: ='ILO Cascade EMESA SOUTH'!N67 -> 8.532 | S32: ='ILO Cascade EMESA SOUTH'!O67 -> 8.55 | T32: ='ILO Cascade EMESA SOUTH'!P67 -> 9.351 | U32: ='ILO Cascade EMESA SOUTH'!Q67 -> 9.0405 | V32: ='ILO Cascade EMESA SOUTH'!R67 -> 11.4075 | W32: ='ILO Cascade EMESA SOUTH'!S67 -> 11.675294 | X32: ='ILO Cascade EMESA SOUTH'!T67 -> 13.304647 | Y32: ='ILO Cascade EMESA SOUTH'!U67 -> 13.484647 | ... AH32: ='ILO Cascade EMESA SOUTH'!AD67 -> 15.3
B33: Inbound Opps | O33: ='Inbound Cascade EMESA NORTH'!K76 | P33: ='Inbound Cascade EMESA NORTH'!L76 | Q33: ='Inbound Cascade EMESA NORTH'!M76 | R33: ='Inbound Cascade EMESA SOUTH'!N67 -> 9.0648 | S33: ='Inbound Cascade EMESA SOUTH'!O67 -> 9.0054 | T33: ='Inbound Cascade EMESA SOUTH'!P67 -> 11.67 | U33: ='Inbound Cascade EMESA SOUTH'!Q67 -> #REF! | V33: ='Inbound Cascade EMESA SOUTH'!R67 -> #REF! | W33: ='Inbound Cascade EMESA SOUTH'!S67 -> #REF! | X33: ='Inbound Cascade EMESA SOUTH'!T67 -> #REF! | Y33: ='Inbound Cascade EMESA SOUTH'!U67 -> #REF! | ... AH33: ='Inbound Cascade EMESA SOUTH'!AD67 -> #REF!
B34: Event Opps | O34: ='Events Cascade EMESA'!K76/2 -> 0 | P34: ='Events Cascade EMESA'!L76/2 -> 0 | Q34: ='Events Cascade EMESA'!M76/2 -> 0 | R34: ='Events Cascade EMESA'!N67/2 -> 1.7355 | S34: ='Events Cascade EMESA'!O67/2 -> 0.8625 | T34: ='Events Cascade EMESA'!P67/2 -> 0.762 | U34: ='Events Cascade EMESA'!Q67/2 -> 1.08375 | V34: ='Events Cascade EMESA'!R67/2 -> 1.12125 | W34: ='Events Cascade EMESA'!S67/2 -> 1.1252206 | X34: ='Events Cascade EMESA'!T67/2 -> 1.1252206 | Y34: ='Events Cascade EMESA'!U67/2 -> 1.1252206 | ... AH34: ='Events Cascade EMESA'!AD67/2 -> 1.125
B35: Partner Opps | O35: ='Partner Cascade EMESA NORTH'!K76 | P35: ='Partner Cascade EMESA NORTH'!L76 | Q35: ='Partner Cascade EMESA NORTH'!M76 | R35: ='Partner Cascade EMESA SOUTH'!N67 -> 1 | S35: ='Partner Cascade EMESA SOUTH'!O67 -> 0 | T35: ='Partner Cascade EMESA SOUTH'!P67 -> 2 | U35: ='Partner Cascade EMESA SOUTH'!Q67 -> 3.75 | V35: ='Partner Cascade EMESA SOUTH'!R67 -> 3.8625 | W35: ='Partner Cascade EMESA SOUTH'!S67 -> 4.132875 | X35: ='Partner Cascade EMESA SOUTH'!T67 -> 4.4221762 | Y35: ='Partner Cascade EMESA SOUTH'!U67 -> 4.7317286 | ... AH35: ='Partner Cascade EMESA SOUTH'!AD67 -> 8.69909
A36: Total EMESA S OCR | O36: =sum(O31:O35) -> 0 | P36: =sum(P31:P35) -> 0 | Q36: =sum(Q31:Q35) -> 0 | R36: =sum(R31:R35) -> 20.9323 | S36: =sum(S31:S35) -> 19.0179 | T36: =sum(T31:T35) -> 23.9825 | U36: =sum(U31:U35) -> #REF! | V36: =sum(V31:V35) -> #REF! | ... AH36: =sum(AH31:AH35) -> #REF!
A37: Total OCR | C37: =SUM(C7:C10) -> 0 | D37: =SUM(D7:D10) -> 0 | E37: =SUM(E7:E10) -> 0 | F37: =SUM(F7:F10) -> 0 | G37: =SUM(G7:G10) -> 0 | H37: =SUM(H7:H10) -> 0 | I37: =SUM(I7:I10) -> 0 | J37: =SUM(J7:J10) -> 0 | ... N37: =SUM(N7:N10) -> 9.7512618 | O37: =O24+O12 -> 26.832112 | P37: =P24+P12 -> 21.657629 | Q37: =Q24+Q12 -> 23.892971 | R37: =R24+R12 -> 47.5676 | S37: =S24+S12 -> 51.9504 | T37: =T24+T12 -> 58.058 | U37: =U24+U12+U36 -> #REF! | V37: =V24+V12+V36 -> #REF! | W37: =W24+W12+W36 -> #REF! | X37: =X24+X12+X36 -> #REF! | Y37: =Y24+Y12+Y36 -> #REF! | Z37: =Z24+Z12+Z36 -> #REF! | AA37: =AA24+AA12+AA36 -> #REF! | AB37: =AB24+AB12+AB36 -> #REF! | ... AH37: =AH24+AH12+AH36 -> #REF!
A38: NORAM | B38: Outbound Opps | C38: ='Outbound Cascade EMESA NORTH'!AG68 -> 0 | D38: ='Outbound Cascade EMESA NORTH'!AH68 -> 0 | E38: ='Outbound Cascade EMESA NORTH'!AI68 -> 0 | F38: ='Outbound Cascade EMESA NORTH'!AJ68 -> 0 | G38: ='Outbound Cascade EMESA NORTH'!AK68 -> 0 | H38: ='Outbound Cascade EMESA NORTH'!AL68 -> 0 | I38: ='Outbound Cascade EMESA NORTH'!AM68 -> 0 | J38: ='Outbound Cascade EMESA NORTH'!AN68 -> 0 | K38: ='Outbound Cascade EMESA NORTH'!AO68/2 -> 0.046735294 | L38: ='Outbound Cascade EMESA NORTH'!AP68/2 -> 0.16214706 | M38: ='Outbound Cascade EMESA NORTH'!AQ68/2 -> 0.25850294 | N38: ='Outbound Cascade EMESA NORTH'!AR68/2 -> 0.31918897 | O38: ='Outbound Cascade EMESA NORTH'!AS68/2 -> 0.34911912 | P38: ='Outbound Cascade EMESA NORTH'!AT68/2 -> 0.36565956 | Q38: ='Outbound Cascade EMESA NORTH'!AU68/2 -> 0.37409853 | R38: ='Outbound Cascade NORAM'!AV68 -> 1.0339706 | S38: ='Outbound Cascade NORAM'!AW68 -> 1.5195876 | T38: ='Outbound Cascade NORAM'!AX68 -> 1.9775897 | U38: ='Outbound Cascade NORAM'!AY68 -> 1.7302824 | V38: ='Outbound Cascade NORAM'!AZ68 -> 1.1246426 | W38: ='Outbound Cascade NORAM'!BA68 -> 0.59724588 | X38: ='Outbound Cascade NORAM'!BB68 -> 0.297525 | Y38: ='Outbound Cascade NORAM'!BC68 -> 0.14106 | ... AH38: ='Outbound Cascade NORAM'!BL68 -> 0
B39: ILO Opps | R39: ='ILO Cascade NORAM'!AV68 -> 4.360251 | S39: ='ILO Cascade NORAM'!AW68 -> 5.9784478 | T39: ='ILO Cascade NORAM'!AX68 -> 7.6398196 | U39: ='ILO Cascade NORAM'!AY68 -> 8.613782 | V39: ='ILO Cascade NORAM'!AZ68 -> 9.7627366 | W39: ='ILO Cascade NORAM'!BA68 -> 11.485649 | X39: ='ILO Cascade NORAM'!BB68 -> 13.122923 | Y39: ='ILO Cascade NORAM'!BC68 -> 14.594166 | ... AH39: ='ILO Cascade NORAM'!BL68 -> 18.742721
B40: Inbound Opps | K40: ='Inbound Cascade NORAM'!AN68 -> 7.8794428 | L40: ='Inbound Cascade NORAM'!AO68 -> 9.9017073 | M40: ='Inbound Cascade NORAM'!AP68 -> 11.36567 | N40: ='Inbound Cascade NORAM'!AQ68 -> 11.653469 | O40: ='Inbound Cascade NORAM'!AR68 -> 11.417128 | P40: ='Inbound Cascade NORAM'!AS68 -> 10.448626 | Q40: ='Inbound Cascade NORAM'!AT68 -> 9.5195602 | R40: ='Inbound Cascade NORAM'!AV68 -> 10.032889 | S40: ='Inbound Cascade NORAM'!AW68 -> 10.874126 | T40: ='Inbound Cascade NORAM'!AX68 -> 11.866924 | U40: ='Inbound Cascade NORAM'!AY68 -> #REF! | V40: ='Inbound Cascade NORAM'!AZ68 -> #REF! | W40: ='Inbound Cascade NORAM'!BA68 -> #REF! | X40: ='Inbound Cascade NORAM'!BB68 -> #REF! | Y40: ='Inbound Cascade NORAM'!BC68 -> #REF! | ... AH40: ='Inbound Cascade NORAM'!BL68 -> #REF!
...

Sheet Inbound Cascade EMESA NORTH
A1: Probability | D1: Q2 22 | E1: Q3 22 | F1: Q4 22 | G1: Q1 23 | H1: Q2 23 | I1: Q3 23 | J1: Q4 23 | K1: Q1 24 | L1: Q2 24 | M1: Q3 24 | N1: Q4 24 | O1: Q1 25 | P1: Q2 25 | Q1: Q3 25 | R1: Q4 25 | S1: {=transpose(A22:A33)} -> Q1 26 | T1: Q2 26 | U1: Q3 26 | V1: Q4 26 | W1: Q1 27 | X1: Q2 27 | Y1: Q3 27 | Z1: Q4 27 | AA1: Q1 28 | AB1: Q2 28 | AC1: Q3 28 | AD1: Q4 28 | AF1: Opps | AG1: Q1 21 | AH1: Q2 21 | AI1: Q3 21 | AJ1: Q4 21 | AK1: Q1 22 | AL1: Q2 22 | AM1: Q3 22 | AN1: Q4 22 | AO1: Q1 23 | AP1: Q2 23 | AQ1: Q3 23 | AR1: Q4 23 | AS1: Q1 24 | AT1: Q2 24 | AU1: Q3 24 | AV1: Q4 24 | AW1: Q1 25 | AX1: Q2 25 | AY1: Q3 25 | AZ1: Q4 25 | BA1: {=transpose(A22:A33)} -> Q1 26 | BB1: Q2 26 | BC1: Q3 26 | BD1: Q4 26 | BE1: Q1 27 | BF1: Q2 27 | BG1: Q3 27 | BH1: Q4 27 | BI1: Q1 28 | BJ1: Q2 28 | BK1: Q3 28 | BL1: Q4 28
A2: Q1 21 | AG2: 0.14 | AH2: 0.33 | AI2: 0.25 | AJ2: 0.15 | AK2: 0.07 | AL2: 0.04 | AM2: 0.02
A3: Q2 21 | AH3: 0.14 | AI3: 0.33 | AJ3: 0.25 | AK3: 0.15 | AL3: 0.07 | AM3: 0.04 | AN3: 0.02
A4: Q3 21 | AI4: 0.14 | AJ4: 0.33 | AK4: 0.25 | AL4: 0.15 | AM4: 0.07 | AN4: 0.04 | AO4: 0.02
A5: Q4 21 | AJ5: 0.14 | AK5: 0.33 | AL5: 0.25 | AM5: 0.15 | AN5: 0.07 | AO5: 0.04 | AP5: 0.02
A6: Q1 22 | D6: 0.1 | AK6: 0.14 | AL6: 0.33 | AM6: 0.25 | AN6: 0.15 | AO6: 0.07 | AP6: 0.04 | AQ6: 0.02
A7: Q2 22 | D7: =227/255 -> 0.89019608 | E7: 0.1 | F7: 0.01 | AL7: 0.14 | AM7: 0.33 | AN7: 0.25 | AO7: 0.15 | AP7: 0.07 | AQ7: 0.04 | AR7: 0.02
A8: Q3 22 | E8: =227/255 -> 0.89019608 | F8: 0.1 | G8: 0.01 | AM8: 0.14 | AN8: 0.33 | AO8: 0.25 | AP8: 0.15 | AQ8: 0.07 | AR8: 0.04 | AS8: 0.02
A9: Q4 22 | F9: =227/255 -> 0.89019608 | G9: 0.1 | H9: 0.01 | AN9: 0.14 | AO9: 0.33 | AP9: 0.25 | AQ9: 0.15 | AR9: 0.07 | AS9: 0.04 | AT9: 0.02
A10: Q1 23 | G10: =227/255 -> 0.89019608 | H10: 0.1 | I10: 0.01 | AO10: 0.14 | AP10: 0.33 | AQ10: 0.25 | AR10: 0.15 | AS10: 0.07 | AT10: 0.04 | AU10: 0.02
A11: Q2 23 | H11: =227/255 -> 0.89019608 | I11: 0.1 | J11: 0.01 | AP11: 0.14 | AQ11: 0.33 | AR11: 0.25 | AS11: 0.15 | AT11: 0.07 | AU11: 0.04 | AV11: 0.02
A12: Q3 23 | I12: =227/255 -> 0.89019608 | J12: 0.1 | K12: 0.01 | AQ12: 0.14 | AR12: 0.33 | AS12: 0.25 | AT12: 0.15 | AU12: 0.07 | AV12: 0.04 | AW12: 0.02
A13: Q4 23 | J13: =227/255 -> 0.89019608 | K13: 0.1 | L13: 0.01 | AR13: 0.14 | AS13: 0.33 | AT13: 0.25 | AU13: 0.15 | AV13: 0.07 | AW13: 0.04 | AX13: 0.02
A14: Q1 24 | K14: =227/255 -> 0.89019608 | L14: 0.1 | M14: 0.01 | AS14: 0.14 | AT14: 0.33 | AU14: 0.25 | AV14: 0.15 | AW14: 0.07 | AX14: 0.04 | AY14: 0.02
A15: Q2 24 | L15: =227/255 -> 0.89019608 | M15: 0.1 | N15: 0.01 | AT15: 0.14 | AU15: 0.33 | AV15: 0.25 | AW15: 0.15 | AX15: 0.07 | AY15: 0.04 | AZ15: 0.02
A16: Q3 24 | M16: =227/255 -> 0.89019608 | N16: 0.1 | O16: 0.01 | AU16: 0.14 | AV16: 0.33 | AW16: 0.25 | AX16: 0.15 | AY16: 0.07 | AZ16: 0.04 | BA16: 0.02
A17: Q4 24 | N17: 0.89 | O17: 0.1 | P17: 0.01 | AV17: 0.14 | AW17: 0.33 | AX17: 0.25 | AY17: 0.15 | AZ17: 0.07 | BA17: 0.04 | BB17: 0.02
A18: Q1 25 | O18: 0.89 | P18: 0.1 | Q18: 0.01 | AW18: 0.14 | AX18: 0.33 | AY18: 0.25 | AZ18: 0.15 | BA18: 0.07 | BB18: 0.04 | BC18: 0.02
A19: Q2 25 | P19: 0.89 | Q19: 0.1 | R19: 0.01 | AX19: 0.14 | AY19: 0.33 | AZ19: 0.25 | BA19: 0.15 | BB19: 0.07 | BC19: 0.04 | BD19: 0.02
A20: Q3 25 | Q20: 0.89 | R20: 0.1 | S20: 0.01 | AY20: 0.14 | AZ20: 0.33 | BA20: 0.25 | BB20: 0.15 | BC20: 0.07 | BD20: 0.04 | BE20: 0.02
A21: Q4 25 | R21: 0.89 | S21: 0.1 | T21: 0.01 | AZ21: 0.14 | BA21: 0.33 | BB21: 0.25 | BC21: 0.15 | BD21: 0.07 | BE21: 0.04 | BF21: 0.02
A22: Q1 26 | S22: =227/255 -> 0.89019608 | T22: 0.1 | U22: 0.01 | BA22: 0.14 | BB22: 0.33 | BC22: 0.25 | BD22: 0.15 | BE22: 0.07 | BF22: 0.04 | BG22: 0.02
A23: Q2 26 | T23: =227/255 -> 0.89019608 | U23: 0.1 | V23: 0.01 | BB23: 0.14 | BC23: 0.33 | BD23: 0.25 | BE23: 0.15 | BF23: 0.07 | BG23: 0.04 | BH23: 0.02
A24: Q3 26 | U24: =227/255 -> 0.89019608 | V24: 0.1 | W24: 0.01 | BC24: 0.14 | BD24: 0.33 | BE24: 0.25 | BF24: 0.15 | BG24: 0.07 | BH24: 0.04 | BI24: 0.02
A25: Q4 26 | V25: =227/255 -> 0.89019608 | W25: 0.1 | X25: 0.01 | BD25: 0.14 | BE25: 0.33 | BF25: 0.25 | BG25: 0.15 | BH25: 0.07 | BI25: 0.04 | BJ25: 0.02
A26: Q1 27 | W26: =227/255 -> 0.89019608 | X26: 0.1 | Y26: 0.01 | BE26: 0.14 | BF26: 0.33 | BG26: 0.25 | BH26: 0.15 | BI26: 0.07 | BJ26: 0.04 | BK26: 0.02
A27: Q2 27 | X27: =227/255 -> 0.89019608 | Y27: 0.1 | Z27: 0.01 | BF27: 0.14 | BG27: 0.33 | BH27: 0.25 | BI27: 0.15 | BJ27: 0.07 | BK27: 0.04 | BL27: 0.02
A28: Q3 27 | Y28: =227/255 -> 0.89019608 | Z28: 0.1 | AA28: 0.01 | BG28: 0.14 | BH28: 0.33 | BI28: 0.25 | BJ28: 0.15 | BK28: 0.07 | BL28: 0.04
A29: Q4 27 | Z29: 0.89 | AA29: 0.1 | AB29: 0.01 | BH29: 0.14 | BI29: 0.33 | BJ29: 0.25 | BK29: 0.15 | BL29: 0.07
A30: Q1 28 | AA30: 0.89 | AB30: 0.1 | AC30: 0.01 | BI30: 0.14 | BJ30: 0.33 | BK30: 0.25 | BL30: 0.15
A31: Q2 28 | AB31: 0.89 | AC31: 0.1 | AD31: 0.01 | BJ31: 0.14 | BK31: 0.33 | BL31: 0.25
A32: Q3 28 | AC32: 0.89 | AD32: 0.1 | BK32: 0.14 | BL32: 0.33
A33: Q4 28 | AD33: 0.89 | BL33: 0.14
B34: SQLs | C34: Conv | D34: Q2 22 | E34: Q3 22 | F34: Q4 22 | G34: Q1 23 | H34: Q2 23 | I34: Q3 23 | J34: Q4 23 | K34: Q1 24 | L34: Q2 24 | M34: Q3 24 | N34: Q4 24 | O34: Q1 25 | P34: Q2 25 | Q34: Q3 25 | R34: Q4 25 | S34: Q1 26 | T34: Q2 26 | U34: Q3 26 | V34: Q4 26 | W34: Q1 27 | X34: Q2 27 | Y34: Q3 27 | Z34: Q4 27 | AA34: Q1 28 | AB34: Q2 28 | AC34: Q3 28 | AD34: Q4 28 | AF34: Opps | AG34: Q1 21 | AH34: Q2 21 | AI34: Q3 21 | AJ34: Q4 21 | AK34: Q1 22 | AL34: Q2 22 | AM34: Q3 22 | AN34: Q4 22 | AO34: Q1 23 | AP34: Q2 23 | AQ34: Q3 23 | AR34: Q4 23 | AS34: Q1 24 | AT34: Q2 24 | AU34: Q3 24 | AV34: Q4 24
A35: Q1 21 | AF35: 0 | AG35: =$AF35*AG2 -> 0 | AH35: =$AF35*AH2 -> 0 | AI35: =$AF35*AI2 -> 0 | AJ35: =$AF35*AJ2 -> 0 | AK35: =$AF35*AK2 -> 0 | AL35: =$AF35*AL2 -> 0 | AM35: =$AF35*AM2 -> 0
A36: Q2 21 | AF36: 0 | AH36: =$AF36*AH3 -> 0 | AI36: =$AF36*AI3 -> 0 | AJ36: =$AF36*AJ3 -> 0 | AK36: =$AF36*AK3 -> 0 | AL36: =$AF36*AL3 -> 0 | AM36: =$AF36*AM3 -> 0 | AN36: =$AF36*AN3 -> 0
A37: Q3 21 | AF37: 0 | AI37: =$AF37*AI4 -> 0 | AJ37: =$AF37*AJ4 -> 0 | AK37: =$AF37*AK4 -> 0 | AL37: =$AF37*AL4 -> 0 | AM37: =$AF37*AM4 -> 0 | AN37: =$AF37*AN4 -> 0 | AO37: =$AF37*AO4 -> 0
A38: Q4 21 | AF38: 0 | AJ38: =$AF38*AJ5 -> 0 | AK38: =$AF38*AK5 -> 0 | AL38: =$AF38*AL5 -> 0 | AM38: =$AF38*AM5 -> 0 | AN38: =$AF38*AN5 -> 0 | AO38: =$AF38*AO5 -> 0 | AP38: =$AF38*AP5 -> 0
A39: Q1 22 | B39: 18 | C39: 0.45 | D39: =$B39*D6 -> 1.8 | AF39: 0 | AK39: =$AF39*AK6 -> 0 | AL39: =$AF39*AL6 -> 0 | AM39: =$AF39*AM6 -> 0 | AN39: =$AF39*AN6 -> 0 | AO39: =$AF39*AO6 -> 0 | AP39: =$AF39*AP6 -> 0 | AQ39: =$AF39*AQ6 -> 0
A40: Q2 22 | B40: 18 | C40: 0.46 | D40: =$B40*D7*$C40 -> 7.3708235 | E40: =$B40*E7*$C40 -> 0.828 | F40: =$B40*F7*$C40 -> 0.0828 | AF40: {=transpose(D67:AD67)} -> 9.1708235 | AL40: =$AF40*AL7 -> 1.2839153 | AM40: =$AF40*AM7 -> 3.0263718 | AN40: =$AF40*AN7 -> 2.2927059 | AO40: =$AF40*AO7 -> 1.3756235 | AP40: =$AF40*AP7 -> 0.64195765 | AQ40: =$AF40*AQ7 -> 0.36683294 | AR40: =$AF40*AR7 -> 0.18341647
...

Sheet Inbound Cascade EMESA SOUTH
A1: Probability | D1: Q2 22 | E1: Q3 22 | F1: Q4 22 | G1: Q1 23 | H1: Q2 23 | I1: Q3 23 | J1: Q4 23 | K1: Q1 24 | L1: Q2 24 | M1: Q3 24 | N1: Q4 24 | O1: Q1 25 | P1: Q2 25 | Q1: Q3 25 | R1: Q4 25 | S1: {=transpose(A22:A33)} -> Q1 26 | T1: Q2 26 | U1: Q3 26 | V1: Q4 26 | W1: Q1 27 | X1: Q2 27 | Y1: Q3 27 | Z1: Q4 27 | AA1: Q1 28 | AB1: Q2 28 | AC1: Q3 28 | AD1: Q4 28 | AF1: Opps | AG1: Q1 21 | AH1: Q2 21 | AI1: Q3 21 | AJ1: Q4 21 | AK1: Q1 22 | AL1: Q2 22 | AM1: Q3 22 | AN1: Q4 22 | AO1: Q1 23 | AP1: Q2 23 | AQ1: Q3 23 | AR1: Q4 23 | AS1: Q1 24 | AT1: Q2 24 | AU1: Q3 24 | AV1: Q4 24 | AW1: Q1 25 | AX1: Q2 25 | AY1: Q3 25 | AZ1: Q4 25 | BA1: {=transpose(A22:A33)} -> Q1 26 | BB1: Q2 26 | BC1: Q3 26 | BD1: Q4 26 | BE1: Q1 27 | BF1: Q2 27 | BG1: Q3 27 | BH1: Q4 27 | BI1: Q1 28 | BJ1: Q2 28 | BK1: Q3 28 | BL1: Q4 28
A2: Q1 21 | AG2: 0.14 | AH2: 0.33 | AI2: 0.25 | AJ2: 0.15 | AK2: 0.07 | AL2: 0.04 | AM2: 0.02
A3: Q2 21 | AH3: 0.14 | AI3: 0.33 | AJ3: 0.25 | AK3: 0.15 | AL3: 0.07 | AM3: 0.04 | AN3: 0.02
A4: Q3 21 | AI4: 0.14 | AJ4: 0.33 | AK4: 0.25 | AL4: 0.15 | AM4: 0.07 | AN4: 0.04 | AO4: 0.02
A5: Q4 21 | AJ5: 0.14 | AK5: 0.33 | AL5: 0.25 | AM5: 0.15 | AN5: 0.07 | AO5: 0.04 | AP5: 0.02
A6: Q1 22 | D6: 0.1 | AK6: 0.14 | AL6: 0.33 | AM6: 0.25 | AN6: 0.15 | AO6: 0.07 | AP6: 0.04 | AQ6: 0.02
A7: Q2 22 | D7: =227/255 -> 0.89019608 | E7: 0.1 | F7: 0.01 | AL7: 0.14 | AM7: 0.33 | AN7: 0.25 | AO7: 0.15 | AP7: 0.07 | AQ7: 0.04 | AR7: 0.02
A8: Q3 22 | E8: =227/255 -> 0.89019608 | F8: 0.1 | G8: 0.01 | AM8: 0.14 | AN8: 0.33 | AO8: 0.25 | AP8: 0.15 | AQ8: 0.07 | AR8: 0.04 | AS8: 0.02
A9: Q4 22 | F9: =227/255 -> 0.89019608 | G9: 0.1 | H9: 0.01 | AN9: 0.14 | AO9: 0.33 | AP9: 0.25 | AQ9: 0.15 | AR9: 0.07 | AS9: 0.04 | AT9: 0.02
A10: Q1 23 | G10: =227/255 -> 0.89019608 | H10: 0.1 | I10: 0.01 | AO10: 0.14 | AP10: 0.33 | AQ10: 0.25 | AR10: 0.15 | AS10: 0.07 | AT10: 0.04 | AU10: 0.02
A11: Q2 23 | H11: =227/255 -> 0.89019608 | I11: 0.1 | J11: 0.01 | AP11: 0.14 | AQ11: 0.33 | AR11: 0.25 | AS11: 0.15 | AT11: 0.07 | AU11: 0.04 | AV11: 0.02
A12: Q3 23 | I12: =227/255 -> 0.89019608 | J12: 0.1 | K12: 0.01 | AQ12: 0.14 | AR12: 0.33 | AS12: 0.25 | AT12: 0.15 | AU12: 0.07 | AV12: 0.04 | AW12: 0.02
A13: Q4 23 | J13: =227/255 -> 0.89019608 | K13: 0.1 | L13: 0.01 | AR13: 0.14 | AS13: 0.33 | AT13: 0.25 | AU13: 0.15 | AV13: 0.07 | AW13: 0.04 | AX13: 0.02
A14: Q1 24 | K14: =227/255 -> 0.89019608 | L14: 0.1 | M14: 0.01 | AS14: 0.14 | AT14: 0.33 | AU14: 0.25 | AV14: 0.15 | AW14: 0.07 | AX14: 0.04 | AY14: 0.02
A15: Q2 24 | L15: =227/255 -> 0.89019608 | M15: 0.1 | N15: 0.01 | AT15: 0.14 | AU15: 0.33 | AV15: 0.25 | AW15: 0.15 | AX15: 0.07 | AY15: 0.04 | AZ15: 0.02
A16: Q3 24 | M16: =227/255 -> 0.89019608 | N16: 0.1 | O16: 0.01 | AU16: 0.14 | AV16: 0.33 | AW16: 0.25 | AX16: 0.15 | AY16: 0.07 | AZ16: 0.04 | BA16: 0.02
A17: Q4 24 | N17: 0.89 | O17: 0.1 | P17: 0.01 | AV17: 0.14 | AW17: 0.33 | AX17: 0.25 | AY17: 0.15 | AZ17: 0.07 | BA17: 0.04 | BB17: 0.02
A18: Q1 25 | O18: 0.89 | P18: 0.1 | Q18: 0.01 | AW18: 0.14 | AX18: 0.33 | AY18: 0.25 | AZ18: 0.15 | BA18: 0.07 | BB18: 0.04 | BC18: 0.02
A19: Q2 25 | P19: 0.89 | Q19: 0.1 | R19: 0.01 | AX19: 0.14 | AY19: 0.33 | AZ19: 0.25 | BA19: 0.15 | BB19: 0.07 | BC19: 0.04 | BD19: 0.02
A20: Q3 25 | Q20: 0.89 | R20: 0.1 | S20: 0.01 | AY20: 0.14 | AZ20: 0.33 | BA20: 0.25 | BB20: 0.15 | BC20: 0.07 | BD20: 0.04 | BE20: 0.02
A21: Q4 25 | R21: 0.89 | S21: 0.1 | T21: 0.01 | AZ21: 0.14 | BA21: 0.33 | BB21: 0.25 | BC21: 0.15 | BD21: 0.07 | BE21: 0.04 | BF21: 0.02
A22: Q1 26 | S22: =227/255 -> 0.89019608 | T22: 0.1 | U22: 0.01 | BA22: 0.14 | BB22: 0.33 | BC22: 0.25 | BD22: 0.15 | BE22: 0.07 | BF22: 0.04 | BG22: 0.02
A23: Q2 26 | T23: =227/255 -> 0.89019608 | U23: 0.1 | V23: 0.01 | BB23: 0.14 | BC23: 0.33 | BD23: 0.25 | BE23: 0.15 | BF23: 0.07 | BG23: 0.04 | BH23: 0.02
